Workbook

Sheet ①使い方・更新手順
A1: 益子工場 生産性管理ファイル 使い方
A3: ■ ファイル構成
A4: ② 釜工程入力 …釜①〜⑤の全工程。黄色セル（商品名・重量・実作業時間）を毎週更新する
A5: ③ スチコン工程入力 …スチコン①〜⑤の全工程。同じく黄色セルを毎週更新する
A6: ④ 前提設定 …時給・固定費等。変更すると全シートに反映
A7: ⑤ 中間品別損益 …自動集計。原材料費を入力すると粗利が算出される
A8: ⑥ 機器別サマリー …釜＋スチコン10機器の生産性比較（自動更新）
A9: ⑦ 釜タイムライン …時間帯別の全釜稼働状況（参考）
A11: ■ 毎週の更新手順（所要時間：約15分）
A12: STEP 1 ②「釜工程入力」シートを開く
A13: → 商品名・開始・終了・重量kgの黄色セルを今週のデータに更新する（追加・削除もOK）
A14: STEP 2 ③「スチコン工程入力」シートも同様に更新
... A35: ■ 追加工程シート一覧（盛り込み・フライヤー・ジェット・カット・製菓）
A36: ⑩盛付梱包工程入力 | B36: 食数・人数・生産性（個/h）を入力
A37: ⑪ZEN工程入力 | B37: 重量・生産性（kg/h）を入力
A38: ⑫ミキサー工程入力 | B38: 重量・生産性（kg/h）を入力
A39: ⑬計量工程入力 | B39: 重量・生産性（kg/h）を入力
A40: ⑭手動工程入力 | B40: 食数・人数・生産性（個/h）を入力
A42: 更新のポイント | B42: 商品名★・食数★・人数★・実作業分★・重量★の黄色セルを毎週入力 → 生産性・労務費が自動計算

Sheet ②釜工程入力
A1: 釜工程入力台帳 毎週更新 | 黄色セル＝入力（商品名・重量・実作業分を更新）
A2: ● 青字・黄背景 = 毎週更新するセル 黒字・グレー = 自動計算（変更不要） | ★R列で中間品名を選ぶと、中間品JAN（S列）で⑱〜⑳に労務費がひもづきます
A4: No. | B4: 釜 | C4: 商品名★ | D4: 開始★ | E4: 終了★ | F4: 稼働(分) | G4: 実作業(分)★ | H4: 人数★ | I4: 重量kg★ | J4: 個数(個)★ 個入力欄 | K4: 生産性 (kg/h) | L4: 生産性 (個/h) | M4: 労務費 (円) | N4: 円/kg | O4: 円/個 | P4: 区分 | Q4: 備考 | R4: ★商品名① | S4: ★商品名② | T4: ★商品名③ | U4: ★商品名④ | V4: ★商品名⑤ | W4: ★商品名⑥ | X4: 振り分け数 自動 | Y4: 1商品あたり 労務費(等分・参考) | Z4: ひもづけ確認 | AA4: 選んだ商品の 食数合計 | AB4: 労務費(数値) | AD4: 配分額① (自動) | AE4: 配分額② (自動) | AF4: 配分額③ (自動) | AG4: 配分額④ (自動) | AH4: 配分額⑤ (自動) | AI4: 配分額⑥ (自動)
A5: 1 | B5: 釜製造 | C5: プリンロール液 | D5: 0.0069444444 | E5: 0.020833333 | F5: 20 | G5: 15 | H5: 1 | I5: 120 | K5: =IF(F5>0,I5/(F5/60),0) | L5: =IF(AND(ISNUMBER(F5),J5>0),J5/(F5/60),"") | M5: =IF(OR(ISNUMBER(SEARCH("サニテーション",C5)),ISNUMBER(SEARCH("客注",C5)),ISNUMBER(SEARCH("切り替え",C5)),ISNUMBER(SEARCH("切替",C5)),NOT(ISNUMBER(H5))),"",IF(ISNUMBER(G5),G5/60*H5*④前提設定!$B$4,IF(AND(G5="",ISNUMBER(F5)),F5/60*H5*④前提設定!$B$4,""))) | N5: =IF(I5>0,M5/I5,"") | O5: =IF(AND(J5>0,ISNUMBER(M5)),M5/J5,"") | R5: 自社製ホイップの卵プリン | X5: =COUNTA(R5:W5) | Y5: =IF(AND($X5>0,ISNUMBER($M5)),$M5/$X5,"") | Z5: =IF($X5=0,"",IF(COUNTIF(⑳商品別1食労務費!$C$5:$C$124,$R5)+COUNTIF(⑳商品別1食労務費!$C$5:$C$124,$S5)+COUNTIF(⑳商品別1食労務費!$C$5:$C$124,$T5)+COUNTIF(⑳商品別1食労務費!$C$5:$C$124,$U5)+COUNTIF(⑳商品別1食労務費!$C$5:$C$124,$V5)+COUNTIF(⑳商品別1食労務費!$C$5:$C$124,$W5)=$X5,"OK","⑳に無い商品名")) | AA5: =SUMIF(⑳商品別1食労務費!$C$5:$C$124,$R5,⑳商品別1食労務費!$F$5:$F$124)+SUMIF(⑳商品別1食労務費!$C$5:$C$124,$S5,⑳商品別1食労務費!$F$5:$F$124)+SUMIF(⑳商品別1食労務費!$C$5:$C$124,$T5,⑳商品別1食労務費!$F$5:$F$124)+SUMIF(⑳商品別1食労務費!$C$5:$C$124,$U5,⑳商品別1食労務費!$F$5:$F$124)+SUMIF(⑳商品別1食労務費!$C$5:$C$124,$V5,⑳商品別1食労務費!$F$5:$F$124)+SUMIF(⑳商品別1食労務費!$C$5:$C$124,$W5,⑳商品別1食労務費!$F$5:$F$124) | AB5: =IF(ISNUMBER($M5),$M5,0) | AD5: =IF($R5="",0,IF($AA5>0,$AB5*SUMIF(⑳商品別1食労務費!$C$5:$C$124,$R5,⑳商品別1食労務費!$F$5:$F$124)/$AA5,$AB5/$X5)) | AE5: =IF($S5="",0,IF($AA5>0,$AB5*SUMIF(⑳商品別1食労務費!$C$5:$C$124,$S5,⑳商品別1食労務費!$F$5:$F$124)/$AA5,$AB5/$X5)) | AF5: =IF($T5="",0,IF($AA5>0,$AB5*SUMIF(⑳商品別1食労務費!$C$5:$C$124,$T5,⑳商品別1食労務費!$F$5:$F$124)/$AA5,$AB5/$X5)) | AG5: =IF($U5="",0,IF($AA5>0,$AB5*SUMIF(⑳商品別1食労務費!$C$5:$C$124,$U5,⑳商品別1食労務費!$F$5:$F$124)/$AA5,$AB5/$X5)) | AH5: =IF($V5="",0,IF($AA5>0,$AB5*SUMIF(⑳商品別1食労務費!$C$5:$C$124,$V5,⑳商品別1食労務費!$F$5:$F$124)/$AA5,$AB5/$X5)) | AI5: =IF($W5="",0,IF($AA5>0,$AB5*SUMIF(⑳商品別1食労務費!$C$5:$C$124,$W5,⑳商品別1食労務費!$F$5:$F$124)/$AA5,$AB5/$X5))
A6: 2 | B6: 釜製造 | C6: あんこ | D6: 0.024305556 | E6: 0.11458333 | F6: 130 | G6: 100 | H6: 1 | I6: 120 | K6: =IF(F6>0,I6/(F6/60),0) | L6: =IF(AND(ISNUMBER(F6),J6>0),J6/(F6/60),"") | M6: =IF(OR(ISNUMBER(SEARCH("サニテーション",C6)),ISNUMBER(SEARCH("客注",C6)),ISNUMBER(SEARCH("切り替え",C6)),ISNUMBER(SEARCH("切替",C6)),NOT(ISNUMBER(H6))),"",IF(ISNUMBER(G6),G6/60*H6*④前提設定!$B$4,IF(AND(G6="",ISNUMBER(F6)),F6/60*H6*④前提設定!$B$4,""))) | N6: =IF(I6>0,M6/I6,"") | O6: =IF(AND(J6>0,ISNUMBER(M6)),M6/J6,"") | Q6: あんこ→おはぎ・どら焼き・あんこＫＩＴに使用（食数の比で配分。⑳で食数を入れてください） | R6: おはぎ | S6: どら焼き | T6: あんこＫＩＴ １ｋｇ | X6: =COUNTA(R6:W6) | Y6: =IF(AND($X6>0,ISNUMBER($M6)),$M6/$X6,"") | Z6: =IF($X6=0,"",IF(COUNTIF(⑳商品別1食労務費!$C$5:$C$124,$R6)+COUNTIF(⑳商品別1食労務費!$C$5:$C$124,$S6)+COUNTIF(⑳商品別1食労務費!$C$5:$C$124,$T6)+COUNTIF(⑳商品別1食労務費!$C$5:$C$124,$U6)+COUNTIF(⑳商品別1食労務費!$C$5:$C$124,$V6)+COUNTIF(⑳商品別1食労務費!$C$5:$C$124,$W6)=$X6,"OK","⑳に無い商品名")) | AA6: =SUMIF(⑳商品別1食労務費!$C$5:$C$124,$R6,⑳商品別1食労務費!$F$5:$F$124)+SUMIF(⑳商品別1食労務費!$C$5:$C$124,$S6,⑳商品別1食労務費!$F$5:$F$124)+SUMIF(⑳商品別1食労務費!$C$5:$C$124,$T6,⑳商品別1食労務費!$F$5:$F$124)+SUMIF(⑳商品別1食労務費!$C$5:$C$124,$U6,⑳商品別1食労務費!$F$5:$F$124)+SUMIF(⑳商品別1食労務費!$C$5:$C$124,$V6,⑳商品別1食労務費!$F$5:$F$124)+SUMIF(⑳商品別1食労務費!$C$5:$C$124,$W6,⑳商品別1食労務費!$F$5:$F$124) | AB6: =IF(ISNUMBER($M6),$M6,0) | AD6: =IF($R6="",0,IF($AA6>0,$AB6*SUMIF(⑳商品別1食労務費!$C$5:$C$124,$R6,⑳商品別1食労務費!$F$5:$F$124)/$AA6,$AB6/$X6)) | AE6: =IF($S6="",0,IF($AA6>0,$AB6*SUMIF(⑳商品別1食労務費!$C$5:$C$124,$S6,⑳商品別1食労務費!$F$5:$F$124)/$AA6,$AB6/$X6)) | AF6: =IF($T6="",0,IF($AA6>0,$AB6*SUMIF(⑳商品別1食労務費!$C$5:$C$124,$T6,⑳商品別1食労務費!$F$5:$F$124)/$AA6,$AB6/$X6)) | AG6: =IF($U6="",0,IF($AA6>0,$AB6*SUMIF(⑳商品別1食労務費!$C$5:$C$124,$U6,⑳商品別1食労務費!$F$5:$F$124)/$AA6,$AB6/$X6)) | AH6: =IF($V6="",0,IF($AA6>0,$AB6*SUMIF(⑳商品別1食労務費!$C$5:$C$124,$V6,⑳商品別1食労務費!$F$5:$F$124)/$AA6,$AB6/$X6)) | AI6: =IF($W6="",0,IF($AA6>0,$AB6*SUMIF(⑳商品別1食労務費!$C$5:$C$124,$W6,⑳商品別1食労務費!$F$5:$F$124)/$AA6,$AB6/$X6))
A7: 3 | B7: 釜製造 | C7: あんこ | F7: 130 | G7: 100 | H7: 1 | I7: 120 | K7: =IF(F7>0,I7/(F7/60),0) | L7: =IF(AND(ISNUMBER(F7),J7>0),J7/(F7/60),"") | M7: =IF(OR(ISNUMBER(SEARCH("サニテーション",C7)),ISNUMBER(SEARCH("客注",C7)),ISNUMBER(SEARCH("切り替え",C7)),ISNUMBER(SEARCH("切替",C7)),NOT(ISNUMBER(H7))),"",IF(ISNUMBER(G7),G7/60*H7*④前提設定!$B$4,IF(AND(G7="",ISNUMBER(F7)),F7/60*H7*④前提設定!$B$4,""))) | N7: =IF(I7>0,M7/I7,"") | O7: =IF(AND(J7>0,ISNUMBER(M7)),M7/J7,"") | Q7: あんこ→おはぎ・どら焼き・あんこＫＩＴに使用（食数の比で配分。⑳で食数を入れてください） | R7: おはぎ | S7: どら焼き | T7: あんこＫＩＴ １ｋｇ | X7: =COUNTA(R7:W7) | Y7: =IF(AND($X7>0,ISNUMBER($M7)),$M7/$X7,"") | Z7: =IF($X7=0,"",IF(COUNTIF(⑳商品別1食労務費!$C$5:$C$124,$R7)+COUNTIF(⑳商品別1食労務費!$C$5:$C$124,$S7)+COUNTIF(⑳商品別1食労務費!$C$5:$C$124,$T7)+COUNTIF(⑳商品別1食労務費!$C$5:$C$124,$U7)+COUNTIF(⑳商品別1食労務費!$C$5:$C$124,$V7)+COUNTIF(⑳商品別1食労務費!$C$5:$C$124,$W7)=$X7,"OK","⑳に無い商品名")) | AA7: =SUMIF(⑳商品別1食労務費!$C$5:$C$124,$R7,⑳商品別1食労務費!$F$5:$F$124)+SUMIF(⑳商品別1食労務費!$C$5:$C$124,$S7,⑳商品別1食労務費!$F$5:$F$124)+SUMIF(⑳商品別1食労務費!$C$5:$C$124,$T7,⑳商品別1食労務費!$F$5:$F$124)+SUMIF(⑳商品別1食労務費!$C$5:$C$124,$U7,⑳商品別1食労務費!$F$5:$F$124)+SUMIF(⑳商品別1食労務費!$C$5:$C$124,$V7,⑳商品別1食労務費!$F$5:$F$124)+SUMIF(⑳商品別1食労務費!$C$5:$C$124,$W7,⑳商品別1食労務費!$F$5:$F$124) | AB7: =IF(ISNUMBER($M7),$M7,0) | AD7: =IF($R7="",0,IF($AA7>0,$AB7*SUMIF(⑳商品別1食労務費!$C$5:$C$124,$R7,⑳商品別1食労務費!$F$5:$F$124)/$AA7,$AB7/$X7)) | AE7: =IF($S7="",0,IF($AA7>0,$AB7*SUMIF(⑳商品別1食労務費!$C$5:$C$124,$S7,⑳商品別1食労務費!$F$5:$F$124)/$AA7,$AB7/$X7)) | AF7: =IF($T7="",0,IF($AA7>0,$AB7*SUMIF(⑳商品別1食労務費!$C$5:$C$124,$T7,⑳商品別1食労務費!$F$5:$F$124)/$AA7,$AB7/$X7)) | AG7: =IF($U7="",0,IF($AA7>0,$AB7*SUMIF(⑳商品別1食労務費!$C$5:$C$124,$U7,⑳商品別1食労務費!$F$5:$F$124)/$AA7,$AB7/$X7)) | AH7: =IF($V7="",0,IF($AA7>0,$AB7*SUMIF(⑳商品別1食労務費!$C$5:$C$124,$V7,⑳商品別1食労務費!$F$5:$F$124)/$AA7,$AB7/$X7)) | AI7: =IF($W7="",0,IF($AA7>0,$AB7*SUMIF(⑳商品別1食労務費!$C$5:$C$124,$W7,⑳商品別1食労務費!$F$5:$F$124)/$AA7,$AB7/$X7))
A8: 4 | B8: 釜製造 | C8: まっしろミルクプリン液 | D8: 0.12152778 | E8: 0.14583333 | F8: 35 | G8: 30 | H8: 1 | I8: 120 | K8: =IF(F8>0,I8/(F8/60),0) | L8: =IF(AND(ISNUMBER(F8),J8>0),J8/(F8/60),"") | M8: =IF(OR(ISNUMBER(SEARCH("サニテーション",C8)),ISNUMBER(SEARCH("客注",C8)),ISNUMBER(SEARCH("切り替え",C8)),ISNUMBER(SEARCH("切替",C8)),NOT(ISNUMBER(H8))),"",IF(ISNUMBER(G8),G8/60*H8*④前提設定!$B$4,IF(AND(G8="",ISNUMBER(F8)),F8/60*H8*④前提設定!$B$4,""))) | N8: =IF(I8>0,M8/I8,"") | O8: =IF(AND(J8>0,ISNUMBER(M8)),M8/J8,"") | R8: まっしろミルクプリン３ | S8: Ｓまっしろミルクプリン小３ | X8: =COUNTA(R8:W8) | Y8: =IF(AND($X8>0,ISNUMBER($M8)),$M8/$X8,"") | Z8: =IF($X8=0,"",IF(COUNTIF(⑳商品別1食労務費!$C$5:$C$124,$R8)+COUNTIF(⑳商品別1食労務費!$C$5:$C$124,$S8)+COUNTIF(⑳商品別1食労務費!$C$5:$C$124,$T8)+COUNTIF(⑳商品別1食労務費!$C$5:$C$124,$U8)+COUNTIF(⑳商品別1食労務費!$C$5:$C$124,$V8)+COUNTIF(⑳商品別1食労務費!$C$5:$C$124,$W8)=$X8,"OK","⑳に無い商品名")) | AA8: =SUMIF(⑳商品別1食労務費!$C$5:$C$124,$R8,⑳商品別1食労務費!$F$5:$F$124)+SUMIF(⑳商品別1食労務費!$C$5:$C$124,$S8,⑳商品別1食労務費!$F$5:$F$124)+SUMIF(⑳商品別1食労務費!$C$5:$C$124,$T8,⑳商品別1食労務費!$F$5:$F$124)+SUMIF(⑳商品別1食労務費!$C$5:$C$124,$U8,⑳商品別1食労務費!$F$5:$F$124)+SUMIF(⑳商品別1食労務費!$C$5:$C$124,$V8,⑳商品別1食労務費!$F$5:$F$124)+SUMIF(⑳商品別1食労務費!$C$5:$C$124,$W8,⑳商品別1食労務費!$F$5:$F$124) | AB8: =IF(ISNUMBER($M8),$M8,0) | AD8: =IF($R8="",0,IF($AA8>0,$AB8*SUMIF(⑳商品別1食労務費!$C$5:$C$124,$R8,⑳商品別1食労務費!$F$5:$F$124)/$AA8,$AB8/$X8)) | AE8: =IF($S8="",0,IF($AA8>0,$AB8*SUMIF(⑳商品別1食労務費!$C$5:$C$124,$S8,⑳商品別1食労務費!$F$5:$F$124)/$AA8,$AB8/$X8)) | AF8: =IF($T8="",0,IF($AA8>0,$AB8*SUMIF(⑳商品別1食労務費!$C$5:$C$124,$T8,⑳商品別1食労務費!$F$5:$F$124)/$AA8,$AB8/$X8)) | AG8: =IF($U8="",0,IF($AA8>0,$AB8*SUMIF(⑳商品別1食労務費!$C$5:$C$124,$U8,⑳商品別1食労務費!$F$5:$F$124)/$AA8,$AB8/$X8)) | AH8: =IF($V8="",0,IF($AA8>0,$AB8*SUMIF(⑳商品別1食労務費!$C$5:$C$124,$V8,⑳商品別1食労務費!$F$5:$F$124)/$AA8,$AB8/$X8)) | AI8: =IF($W8="",0,IF($AA8>0,$AB8*SUMIF(⑳商品別1食労務費!$C$5:$C$124,$W8,⑳商品別1食労務費!$F$5:$F$124)/$AA8,$AB8/$X8))
A9: 5 | B9: 釜製造 | C9: まっしろミルクプリン液 | F9: 35 | G9: 30 | H9: 1 | I9: 120 | K9: =IF(F9>0,I9/(F9/60),0) | L9: =IF(AND(ISNUMBER(F9),J9>0),J9/(F9/60),"") | M9: =IF(OR(ISNUMBER(SEARCH("サニテーション",C9)),ISNUMBER(SEARCH("客注",C9)),ISNUMBER(SEARCH("切り替え",C9)),ISNUMBER(SEARCH("切替",C9)),NOT(ISNUMBER(H9))),"",IF(ISNUMBER(G9),G9/60*H9*④前提設定!$B$4,IF(AND(G9="",ISNUMBER(F9)),F9/60*H9*④前提設定!$B$4,""))) | N9: =IF(I9>0,M9/I9,"") | O9: =IF(AND(J9>0,ISNUMBER(M9)),M9/J9,"") | R9: まっしろミルクプリン３ | S9: Ｓまっしろミルクプリン小３ | X9: =COUNTA(R9:W9) | Y9: =IF(AND($X9>0,ISNUMBER($M9)),$M9/$X9,"") | Z9: =IF($X9=0,"",IF(COUNTIF(⑳商品別1食労務費!$C$5:$C$124,$R9)+COUNTIF(⑳商品別1食労務費!$C$5:$C$124,$S9)+COUNTIF(⑳商品別1食労務費!$C$5:$C$124,$T9)+COUNTIF(⑳商品別1食労務費!$C$5:$C$124,$U9)+COUNTIF(⑳商品別1食労務費!$C$5:$C$124,$V9)+COUNTIF(⑳商品別1食労務費!$C$5:$C$124,$W9)=$X9,"OK","⑳に無い商品名")) | AA9: =SUMIF(⑳商品別1食労務費!$C$5:$C$124,$R9,⑳商品別1食労務費!$F$5:$F$124)+SUMIF(⑳商品別1食労務費!$C$5:$C$124,$S9,⑳商品別1食労務費!$F$5:$F$124)+SUMIF(⑳商品別1食労務費!$C$5:$C$124,$T9,⑳商品別1食労務費!$F$5:$F$124)+SUMIF(⑳商品別1食労務費!$C$5:$C$124,$U9,⑳商品別1食労務費!$F$5:$F$124)+SUMIF(⑳商品別1食労務費!$C$5:$C$124,$V9,⑳商品別1食労務費!$F$5:$F$124)+SUMIF(⑳商品別1食労務費!$C$5:$C$124,$W9,⑳商品別1食労務費!$F$5:$F$124) | AB9: =IF(ISNUMBER($M9),$M9,0) | AD9: =IF($R9="",0,IF($AA9>0,$AB9*SUMIF(⑳商品別1食労務費!$C$5:$C$124,$R9,⑳商品別1食労務費!$F$5:$F$124)/$AA9,$AB9/$X9)) | AE9: =IF($S9="",0,IF($AA9>0,$AB9*SUMIF(⑳商品別1食労務費!$C$5:$C$124,$S9,⑳商品別1食労務費!$F$5:$F$124)/$AA9,$AB9/$X9)) | AF9: =IF($T9="",0,IF($AA9>0,$AB9*SUMIF(⑳商品別1食労務費!$C$5:$C$124,$T9,⑳商品別1食労務費!$F$5:$F$124)/$AA9,$AB9/$X9)) | AG9: =IF($U9="",0,IF($AA9>0,$AB9*SUMIF(⑳商品別1食労務費!$C$5:$C$124,$U9,⑳商品別1食労務費!$F$5:$F$124)/$AA9,$AB9/$X9)) | AH9: =IF($V9="",0,IF($AA9>0,$AB9*SUMIF(⑳商品別1食労務費!$C$5:$C$124,$V9,⑳商品別1食労務費!$F$5:$F$124)/$AA9,$AB9/$X9)) | AI9: =IF($W9="",0,IF($AA9>0,$AB9*SUMIF(⑳商品別1食労務費!$C$5:$C$124,$W9,⑳商品別1食労務費!$F$5:$F$124)/$AA9,$AB9/$X9))
A10: 6 | B10: 釜製造 | C10: みかん牛乳寒天 | D10: 0.14930556 | E10: 0.19444444 | F10: 65 | G10: 40 | H10: 1 | I10: 120 | K10: =IF(F10>0,I10/(F10/60),0) | L10: =IF(AND(ISNUMBER(F10),J10>0),J10/(F10/60),"") | M10: =IF(OR(ISNUMBER(SEARCH("サニテーション",C10)),ISNUMBER(SEARCH("客注",C10)),ISNUMBER(SEARCH("切り替え",C10)),ISNUMBER(SEARCH("切替",C10)),NOT(ISNUMBER(H10))),"",IF(ISNUMBER(G10),G10/60*H10*④前提設定!$B$4,IF(AND(G10="",ISNUMBER(F10)),F10/60*H10*④前提設定!$B$4,""))) | N10: =IF(I10>0,M10/I10,"") | O10: =IF(AND(J10>0,ISNUMBER(M10)),M10/J10,"") | R10: みかんの牛乳寒天２ | S10: みかんの牛乳寒天 小 | T10: Ｓみかんの牛乳寒天 小 | X10: =COUNTA(R10:W10) | Y10: =IF(AND($X10>0,ISNUMBER($M10)),$M10/$X10,"") | Z10: =IF($X10=0,"",IF(COUNTIF(⑳商品別1食労務費!$C$5:$C$124,$R10)+COUNTIF(⑳商品別1食労務費!$C$5:$C$124,$S10)+COUNTIF(⑳商品別1食労務費!$C$5:$C$124,$T10)+COUNTIF(⑳商品別1食労務費!$C$5:$C$124,$U10)+COUNTIF(⑳商品別1食労務費!$C$5:$C$124,$V10)+COUNTIF(⑳商品別1食労務費!$C$5:$C$124,$W10)=$X10,"OK","⑳に無い商品名")) | AA10: =SUMIF(⑳商品別1食労務費!$C$5:$C$124,$R10,⑳商品別1食労務費!$F$5:$F$124)+SUMIF(⑳商品別1食労務費!$C$5:$C$124,$S10,⑳商品別1食労務費!$F$5:$F$124)+SUMIF(⑳商品別1食労務費!$C$5:$C$124,$T10,⑳商品別1食労務費!$F$5:$F$124)+SUMIF(⑳商品別1食労務費!$C$5:$C$124,$U10,⑳商品別1食労務費!$F$5:$F$124)+SUMIF(⑳商品別1食労務費!$C$5:$C$124,$V10,⑳商品別1食労務費!$F$5:$F$124)+SUMIF(⑳商品別1食労務費!$C$5:$C$124,$W10,⑳商品別1食労務費!$F$5:$F$124) | AB10: =IF(ISNUMBER($M10),$M10,0) | AD10: =IF($R10="",0,IF($AA10>0,$AB10*SUMIF(⑳商品別1食労務費!$C$5:$C$124,$R10,⑳商品別1食労務費!$F$5:$F$124)/$AA10,$AB10/$X10)) | AE10: =IF($S10="",0,IF($AA10>0,$AB10*SUMIF(⑳商品別1食労務費!$C$5:$C$124,$S10,⑳商品別1食労務費!$F$5:$F$124)/$AA10,$AB10/$X10)) | AF10: =IF($T10="",0,IF($AA10>0,$AB10*SUMIF(⑳商品別1食労務費!$C$5:$C$124,$T10,⑳商品別1食労務費!$F$5:$F$124)/$AA10,$AB10/$X10)) | AG10: =IF($U10="",0,IF($AA10>0,$AB10*SUMIF(⑳商品別1食労務費!$C$5:$C$124,$U10,⑳商品別1食労務費!$F$5:$F$124)/$AA10,$AB10/$X10)) | AH10: =IF($V10="",0,IF($AA10>0,$AB10*SUMIF(⑳商品別1食労務費!$C$5:$C$124,$V10,⑳商品別1食労務費!$F$5:$F$124)/$AA10,$AB10/$X10)) | AI10: =IF($W10="",0,IF($AA10>0,$AB10*SUMIF(⑳商品別1食労務費!$C$5:$C$124,$W10,⑳商品別1食労務費!$F$5:$F$124)/$AA10,$AB10/$X10))
A11: 7 | B11: 釜製造 | C11: コーヒーゼリー液 | D11: 0.20138889 | E11: 0.33680556 | F11: 195 | G11: 100 | H11: 1 | I11: 120 | K11: =IF(F11>0,I11/(F11/60),0) | L11: =IF(AND(ISNUMBER(F11),J11>0),J11/(F11/60),"") | M11: =IF(OR(ISNUMBER(SEARCH("サニテーション",C11)),ISNUMBER(SEARCH("客注",C11)),ISNUMBER(SEARCH("切り替え",C11)),ISNUMBER(SEARCH("切替",C11)),NOT(ISNUMBER(H11))),"",IF(ISNUMBER(G11),G11/60*H11*④前提設定!$B$4,IF(AND(G11="",ISNUMBER(F11)),F11/60*H11*④前提設定!$B$4,""))) | N11: =IF(I11>0,M11/I11,"") | O11: =IF(AND(J11>0,ISNUMBER(M11)),M11/J11,"") | R11: 大人のコーヒーゼリー４ | S11: Ｓ大人のコーヒーゼリー４ | T11: 大人のコーヒーゼリー小４ | U11: Ｓ大人のコーヒーゼリー小４ | X11: =COUNTA(R11:W11) | Y11: =IF(AND($X11>0,ISNUMBER($M11)),$M11/$X11,"") | Z11: =IF($X11=0,"",IF(COUNTIF(⑳商品別1食労務費!$C$5:$C$124,$R11)+COUNTIF(⑳商品別1食労務費!$C$5:$C$124,$S11)+COUNTIF(⑳商品別1食労務費!$C$5:$C$124,$T11)+COUNTIF(⑳商品別1食労務費!$C$5:$C$124,$U11)+COUNTIF(⑳商品別1食労務費!$C$5:$C$124,$V11)+COUNTIF(⑳商品別1食労務費!$C$5:$C$124,$W11)=$X11,"OK","⑳に無い商品名")) | AA11: =SUMIF(⑳商品別1食労務費!$C$5:$C$124,$R11,⑳商品別1食労務費!$F$5:$F$124)+SUMIF(⑳商品別1食労務費!$C$5:$C$124,$S11,⑳商品別1食労務費!$F$5:$F$124)+SUMIF(⑳商品別1食労務費!$C$5:$C$124,$T11,⑳商品別1食労務費!$F$5:$F$124)+SUMIF(⑳商品別1食労務費!$C$5:$C$124,$U11,⑳商品別1食労務費!$F$5:$F$124)+SUMIF(⑳商品別1食労務費!$C$5:$C$124,$V11,⑳商品別1食労務費!$F$5:$F$124)+SUMIF(⑳商品別1食労務費!$C$5:$C$124,$W11,⑳商品別1食労務費!$F$5:$F$124) | AB11: =IF(ISNUMBER($M11),$M11,0) | AD11: =IF($R11="",0,IF($AA11>0,$AB11*SUMIF(⑳商品別1食労務費!$C$5:$C$124,$R11,⑳商品別1食労務費!$F$5:$F$124)/$AA11,$AB11/$X11)) | AE11: =IF($S11="",0,IF($AA11>0,$AB11*SUMIF(⑳商品別1食労務費!$C$5:$C$124,$S11,⑳商品別1食労務費!$F$5:$F$124)/$AA11,$AB11/$X11)) | AF11: =IF($T11="",0,IF($AA11>0,$AB11*SUMIF(⑳商品別1食労務費!$C$5:$C$124,$T11,⑳商品別1食労務費!$F$5:$F$124)/$AA11,$AB11/$X11)) | AG11: =IF($U11="",0,IF($AA11>0,$AB11*SUMIF(⑳商品別1食労務費!$C$5:$C$124,$U11,⑳商品別1食労務費!$F$5:$F$124)/$AA11,$AB11/$X11)) | AH11: =IF($V11="",0,IF($AA11>0,$AB11*SUMIF(⑳商品別1食労務費!$C$5:$C$124,$V11,⑳商品別1食労務費!$F$5:$F$124)/$AA11,$AB11/$X11)) | AI11: =IF($W11="",0,IF($AA11>0,$AB11*SUMIF(⑳商品別1食労務費!$C$5:$C$124,$W11,⑳商品別1食労務費!$F$5:$F$124)/$AA11,$AB11/$X11))
A12: 8 | B12: 釜製造 | C12: コーヒーゼリー液 | F12: 195 | G12: 100 | H12: 1 | I12: 120 | K12: =IF(F12>0,I12/(F12/60),0) | L12: =IF(AND(ISNUMBER(F12),J12>0),J12/(F12/60),"") | M12: =IF(OR(ISNUMBER(SEARCH("サニテーション",C12)),ISNUMBER(SEARCH("客注",C12)),ISNUMBER(SEARCH("切り替え",C12)),ISNUMBER(SEARCH("切替",C12)),NOT(ISNUMBER(H12))),"",IF(ISNUMBER(G12),G12/60*H12*④前提設定!$B$4,IF(AND(G12="",ISNUMBER(F12)),F12/60*H12*④前提設定!$B$4,""))) | N12: =IF(I12>0,M12/I12,"") | O12: =IF(AND(J12>0,ISNUMBER(M12)),M12/J12,"") | R12: 大人のコーヒーゼリー４ | S12: Ｓ大人のコーヒーゼリー４ | T12: 大人のコーヒーゼリー小４ | U12: Ｓ大人のコーヒーゼリー小４ | X12: =COUNTA(R12:W12) | Y12: =IF(AND($X12>0,ISNUMBER($M12)),$M12/$X12,"") | Z12: =IF($X12=0,"",IF(COUNTIF(⑳商品別1食労務費!$C$5:$C$124,$R12)+COUNTIF(⑳商品別1食労務費!$C$5:$C$124,$S12)+COUNTIF(⑳商品別1食労務費!$C$5:$C$124,$T12)+COUNTIF(⑳商品別1食労務費!$C$5:$C$124,$U12)+COUNTIF(⑳商品別1食労務費!$C$5:$C$124,$V12)+COUNTIF(⑳商品別1食労務費!$C$5:$C$124,$W12)=$X12,"OK","⑳に無い商品名")) | AA12: =SUMIF(⑳商品別1食労務費!$C$5:$C$124,$R12,⑳商品別1食労務費!$F$5:$F$124)+SUMIF(⑳商品別1食労務費!$C$5:$C$124,$S12,⑳商品別1食労務費!$F$5:$F$124)+SUMIF(⑳商品別1食労務費!$C$5:$C$124,$T12,⑳商品別1食労務費!$F$5:$F$124)+SUMIF(⑳商品別1食労務費!$C$5:$C$124,$U12,⑳商品別1食労務費!$F$5:$F$124)+SUMIF(⑳商品別1食労務費!$C$5:$C$124,$V12,⑳商品別1食労務費!$F$5:$F$124)+SUMIF(⑳商品別1食労務費!$C$5:$C$124,$W12,⑳商品別1食労務費!$F$5:$F$124) | AB12: =IF(ISNUMBER($M12),$M12,0) | AD12: =IF($R12="",0,IF($AA12>0,$AB12*SUMIF(⑳商品別1食労務費!$C$5:$C$124,$R12,⑳商品別1食労務費!$F$5:$F$124)/$AA12,$AB12/$X12)) | AE12: =IF($S12="",0,IF($AA12>0,$AB12*SUMIF(⑳商品別1食労務費!$C$5:$C$124,$S12,⑳商品別1食労務費!$F$5:$F$124)/$AA12,$AB12/$X12)) | AF12: =IF($T12="",0,IF($AA12>0,$AB12*SUMIF(⑳商品別1食労務費!$C$5:$C$124,$T12,⑳商品別1食労務費!$F$5:$F$124)/$AA12,$AB12/$X12)) | AG12: =IF($U12="",0,IF($AA12>0,$AB12*SUMIF(⑳商品別1食労務費!$C$5:$C$124,$U12,⑳商品別1食労務費!$F$5:$F$124)/$AA12,$AB12/$X12)) | AH12: =IF($V12="",0,IF($AA12>0,$AB12*SUMIF(⑳商品別1食労務費!$C$5:$C$124,$V12,⑳商品別1食労務費!$F$5:$F$124)/$AA12,$AB12/$X12)) | AI12: =IF($W12="",0,IF($AA12>0,$AB12*SUMIF(⑳商品別1食労務費!$C$5:$C$124,$W12,⑳商品別1食労務費!$F$5:$F$124)/$AA12,$AB12/$X12))
A13: 9 | B13: 釜製造 | C13: コーヒーゼリー液 | F13: 195 | G13: 100 | H13: 1 | I13: 120 | K13: =IF(F13>0,I13/(F13/60),0) | L13: =IF(AND(ISNUMBER(F13),J13>0),J13/(F13/60),"") | M13: =IF(OR(ISNUMBER(SEARCH("サニテーション",C13)),ISNUMBER(SEARCH("客注",C13)),ISNUMBER(SEARCH("切り替え",C13)),ISNUMBER(SEARCH("切替",C13)),NOT(ISNUMBER(H13))),"",IF(ISNUMBER(G13),G13/60*H13*④前提設定!$B$4,IF(AND(G13="",ISNUMBER(F13)),F13/60*H13*④前提設定!$B$4,""))) | N13: =IF(I13>0,M13/I13,"") | O13: =IF(AND(J13>0,ISNUMBER(M13)),M13/J13,"") | R13: 大人のコーヒーゼリー４ | S13: Ｓ大人のコーヒーゼリー４ | T13: 大人のコーヒーゼリー小４ | U13: Ｓ大人のコーヒーゼリー小４ | X13: =COUNTA(R13:W13) | Y13: =IF(AND($X13>0,ISNUMBER($M13)),$M13/$X13,"") | Z13: =IF($X13=0,"",IF(COUNTIF(⑳商品別1食労務費!$C$5:$C$124,$R13)+COUNTIF(⑳商品別1食労務費!$C$5:$C$124,$S13)+COUNTIF(⑳商品別1食労務費!$C$5:$C$124,$T13)+COUNTIF(⑳商品別1食労務費!$C$5:$C$124,$U13)+COUNTIF(⑳商品別1食労務費!$C$5:$C$124,$V13)+COUNTIF(⑳商品別1食労務費!$C$5:$C$124,$W13)=$X13,"OK","⑳に無い商品名")) | AA13: =SUMIF(⑳商品別1食労務費!$C$5:$C$124,$R13,⑳商品別1食労務費!$F$5:$F$124)+SUMIF(⑳商品別1食労務費!$C$5:$C$124,$S13,⑳商品別1食労務費!$F$5:$F$124)+SUMIF(⑳商品別1食労務費!$C$5:$C$124,$T13,⑳商品別1食労務費!$F$5:$F$124)+SUMIF(⑳商品別1食労務費!$C$5:$C$124,$U13,⑳商品別1食労務費!$F$5:$F$124)+SUMIF(⑳商品別1食労務費!$C$5:$C$124,$V13,⑳商品別1食労務費!$F$5:$F$124)+SUMIF(⑳商品別1食労務費!$C$5:$C$124,$W13,⑳商品別1食労務費!$F$5:$F$124) | AB13: =IF(ISNUMBER($M13),$M13,0) | AD13: =IF($R13="",0,IF($AA13>0,$AB13*SUMIF(⑳商品別1食労務費!$C$5:$C$124,$R13,⑳商品別1食労務費!$F$5:$F$124)/$AA13,$AB13/$X13)) | AE13: =IF($S13="",0,IF($AA13>0,$AB13*SUMIF(⑳商品別1食労務費!$C$5:$C$124,$S13,⑳商品別1食労務費!$F$5:$F$124)/$AA13,$AB13/$X13)) | AF13: =IF($T13="",0,IF($AA13>0,$AB13*SUMIF(⑳商品別1食労務費!$C$5:$C$124,$T13,⑳商品別1食労務費!$F$5:$F$124)/$AA13,$AB13/$X13)) | AG13: =IF($U13="",0,IF($AA13>0,$AB13*SUMIF(⑳商品別1食労務費!$C$5:$C$124,$U13,⑳商品別1食労務費!$F$5:$F$124)/$AA13,$AB13/$X13)) | AH13: =IF($V13="",0,IF($AA13>0,$AB13*SUMIF(⑳商品別1食労務費!$C$5:$C$124,$V13,⑳商品別1食労務費!$F$5:$F$124)/$AA13,$AB13/$X13)) | AI13: =IF($W13="",0,IF($AA13>0,$AB13*SUMIF(⑳商品別1食労務費!$C$5:$C$124,$W13,⑳商品別1食労務費!$F$5:$F$124)/$AA13,$AB13/$X13))
A14: 10 | B14: 釜製造 | C14: ブルーベリーソース | D14: 0.45138889 | E14: 0.46180556 | F14: 15 | G14: 10 | H14: 1 | I14: 30 | K14: =IF(F14>0,I14/(F14/60),0) | L14: =IF(AND(ISNUMBER(F14),J14>0),J14/(F14/60),"") | M14: =IF(OR(ISNUMBER(SEARCH("サニテーション",C14)),ISNUMBER(SEARCH("客注",C14)),ISNUMBER(SEARCH("切り替え",C14)),ISNUMBER(SEARCH("切替",C14)),NOT(ISNUMBER(H14))),"",IF(ISNUMBER(G14),G14/60*H14*④前提設定!$B$4,IF(AND(G14="",ISNUMBER(F14)),F14/60*H14*④前提設定!$B$4,""))) | N14: =IF(I14>0,M14/I14,"") | O14: =IF(AND(J14>0,ISNUMBER(M14)),M14/J14,"") | R14: Ｓ２層仕立てのチーズケーキ | S14: ２層仕立てのチーズケーキ | X14: =COUNTA(R14:W14) | Y14: =IF(AND($X14>0,ISNUMBER($M14)),$M14/$X14,"") | Z14: =IF($X14=0,"",IF(COUNTIF(⑳商品別1食労務費!$C$5:$C$124,$R14)+COUNTIF(⑳商品別1食労務費!$C$5:$C$124,$S14)+COUNTIF(⑳商品別1食労務費!$C$5:$C$124,$T14)+COUNTIF(⑳商品別1食労務費!$C$5:$C$124,$U14)+COUNTIF(⑳商品別1食労務費!$C$5:$C$124,$V14)+COUNTIF(⑳商品別1食労務費!$C$5:$C$124,$W14)=$X14,"OK","⑳に無い商品名")) | AA14: =SUMIF(⑳商品別1食労務費!$C$5:$C$124,$R14,⑳商品別1食労務費!$F$5:$F$124)+SUMIF(⑳商品別1食労務費!$C$5:$C$124,$S14,⑳商品別1食労務費!$F$5:$F$124)+SUMIF(⑳商品別1食労務費!$C$5:$C$124,$T14,⑳商品別1食労務費!$F$5:$F$124)+SUMIF(⑳商品別1食労務費!$C$5:$C$124,$U14,⑳商品別1食労務費!$F$5:$F$124)+SUMIF(⑳商品別1食労務費!$C$5:$C$124,$V14,⑳商品別1食労務費!$F$5:$F$124)+SUMIF(⑳商品別1食労務費!$C$5:$C$124,$W14,⑳商品別1食労務費!$F$5:$F$124) | AB14: =IF(ISNUMBER($M14),$M14,0) | AD14: =IF($R14="",0,IF($AA14>0,$AB14*SUMIF(⑳商品別1食労務費!$C$5:$C$124,$R14,⑳商品別1食労務費!$F$5:$F$124)/$AA14,$AB14/$X14)) | AE14: =IF($S14="",0,IF($AA14>0,$AB14*SUMIF(⑳商品別1食労務費!$C$5:$C$124,$S14,⑳商品別1食労務費!$F$5:$F$124)/$AA14,$AB14/$X14)) | AF14: =IF($T14="",0,IF($AA14>0,$AB14*SUMIF(⑳商品別1食労務費!$C$5:$C$124,$T14,⑳商品別1食労務費!$F$5:$F$124)/$AA14,$AB14/$X14)) | AG14: =IF($U14="",0,IF($AA14>0,$AB14*SUMIF(⑳商品別1食労務費!$C$5:$C$124,$U14,⑳商品別1食労務費!$F$5:$F$124)/$AA14,$AB14/$X14)) | AH14: =IF($V14="",0,IF($AA14>0,$AB14*SUMIF(⑳商品別1食労務費!$C$5:$C$124,$V14,⑳商品別1食労務費!$F$5:$F$124)/$AA14,$AB14/$X14)) | AI14: =IF($W14="",0,IF($AA14>0,$AB14*SUMIF(⑳商品別1食労務費!$C$5:$C$124,$W14,⑳商品別1食労務費!$F$5:$F$124)/$AA14,$AB14/$X14))
A15: 11 | B15: 釜製造 | C15: ブルーベリーソース | F15: 15 | G15: 10 | H15: 1 | I15: 30 | K15: =IF(F15>0,I15/(F15/60),0) | L15: =IF(AND(ISNUMBER(F15),J15>0),J15/(F15/60),"") | M15: =IF(OR(ISNUMBER(SEARCH("サニテーション",C15)),ISNUMBER(SEARCH("客注",C15)),ISNUMBER(SEARCH("切り替え",C15)),ISNUMBER(SEARCH("切替",C15)),NOT(ISNUMBER(H15))),"",IF(ISNUMBER(G15),G15/60*H15*④前提設定!$B$4,IF(AND(G15="",ISNUMBER(F15)),F15/60*H15*④前提設定!$B$4,""))) | N15: =IF(I15>0,M15/I15,"") | O15: =IF(AND(J15>0,ISNUMBER(M15)),M15/J15,"") | R15: Ｓ２層仕立てのチーズケーキ | S15: ２層仕立てのチーズケーキ | X15: =COUNTA(R15:W15) | Y15: =IF(AND($X15>0,ISNUMBER($M15)),$M15/$X15,"") | Z15: =IF($X15=0,"",IF(COUNTIF(⑳商品別1食労務費!$C$5:$C$124,$R15)+COUNTIF(⑳商品別1食労務費!$C$5:$C$124,$S15)+COUNTIF(⑳商品別1食労務費!$C$5:$C$124,$T15)+COUNTIF(⑳商品別1食労務費!$C$5:$C$124,$U15)+COUNTIF(⑳商品別1食労務費!$C$5:$C$124,$V15)+COUNTIF(⑳商品別1食労務費!$C$5:$C$124,$W15)=$X15,"OK","⑳に無い商品名")) | AA15: =SUMIF(⑳商品別1食労務費!$C$5:$C$124,$R15,⑳商品別1食労務費!$F$5:$F$124)+SUMIF(⑳商品別1食労務費!$C$5:$C$124,$S15,⑳商品別1食労務費!$F$5:$F$124)+SUMIF(⑳商品別1食労務費!$C$5:$C$124,$T15,⑳商品別1食労務費!$F$5:$F$124)+SUMIF(⑳商品別1食労務費!$C$5:$C$124,$U15,⑳商品別1食労務費!$F$5:$F$124)+SUMIF(⑳商品別1食労務費!$C$5:$C$124,$V15,⑳商品別1食労務費!$F$5:$F$124)+SUMIF(⑳商品別1食労務費!$C$5:$C$124,$W15,⑳商品別1食労務費!$F$5:$F$124) | AB15: =IF(ISNUMBER($M15),$M15,0) | AD15: =IF($R15="",0,IF($AA15>0,$AB15*SUMIF(⑳商品別1食労務費!$C$5:$C$124,$R15,⑳商品別1食労務費!$F$5:$F$124)/$AA15,$AB15/$X15)) | AE15: =IF($S15="",0,IF($AA15>0,$AB15*SUMIF(⑳商品別1食労務費!$C$5:$C$124,$S15,⑳商品別1食労務費!$F$5:$F$124)/$AA15,$AB15/$X15)) | AF15: =IF($T15="",0,IF($AA15>0,$AB15*SUMIF(⑳商品別1食労務費!$C$5:$C$124,$T15,⑳商品別1食労務費!$F$5:$F$124)/$AA15,$AB15/$X15)) | AG15: =IF($U15="",0,IF($AA15>0,$AB15*SUMIF(⑳商品別1食労務費!$C$5:$C$124,$U15,⑳商品別1食労務費!$F$5:$F$124)/$AA15,$AB15/$X15)) | AH15: =IF($V15="",0,IF($AA15>0,$AB15*SUMIF(⑳商品別1食労務費!$C$5:$C$124,$V15,⑳商品別1食労務費!$F$5:$F$124)/$AA15,$AB15/$X15)) | AI15: =IF($W15="",0,IF($AA15>0,$AB15*SUMIF(⑳商品別1食労務費!$C$5:$C$124,$W15,⑳商品別1食労務費!$F$5:$F$124)/$AA15,$AB15/$X15))
A16: 12 | B16: 釜製造 | C16: 自社製ホイップの卵プリン | D16: 0.49305556 | E16: 0.56944444 | F16: 110 | G16: 90 | H16: 2 | I16: 120 | K16: =IF(F16>0,I16/(F16/60),0) | L16: =IF(AND(ISNUMBER(F16),J16>0),J16/(F16/60),"") | M16: =IF(OR(ISNUMBER(SEARCH("サニテーション",C16)),ISNUMBER(SEARCH("客注",C16)),ISNUMBER(SEARCH("切り替え",C16)),ISNUMBER(SEARCH("切替",C16)),NOT(ISNUMBER(H16))),"",IF(ISNUMBER(G16),G16/60*H16*④前提設定!$B$4,IF(AND(G16="",ISNUMBER(F16)),F16/60*H16*④前提設定!$B$4,""))) | N16: =IF(I16>0,M16/I16,"") | O16: =IF(AND(J16>0,ISNUMBER(M16)),M16/J16,"") | R16: 自社製ホイップの卵プリン | S16: Ｓホイップの卵プリン | T16: ホイップの卵プリン | X16: =COUNTA(R16:W16) | Y16: =IF(AND($X16>0,ISNUMBER($M16)),$M16/$X16,"") | Z16: =IF($X16=0,"",IF(COUNTIF(⑳商品別1食労務費!$C$5:$C$124,$R16)+COUNTIF(⑳商品別1食労務費!$C$5:$C$124,$S16)+COUNTIF(⑳商品別1食労務費!$C$5:$C$124,$T16)+COUNTIF(⑳商品別1食労務費!$C$5:$C$124,$U16)+COUNTIF(⑳商品別1食労務費!$C$5:$C$124,$V16)+COUNTIF(⑳商品別1食労務費!$C$5:$C$124,$W16)=$X16,"OK","⑳に無い商品名")) | AA16: =SUMIF(⑳商品別1食労務費!$C$5:$C$124,$R16,⑳商品別1食労務費!$F$5:$F$124)+SUMIF(⑳商品別1食労務費!$C$5:$C$124,$S16,⑳商品別1食労務費!$F$5:$F$124)+SUMIF(⑳商品別1食労務費!$C$5:$C$124,$T16,⑳商品別1食労務費!$F$5:$F$124)+SUMIF(⑳商品別1食労務費!$C$5:$C$124,$U16,⑳商品別1食労務費!$F$5:$F$124)+SUMIF(⑳商品別1食労務費!$C$5:$C$124,$V16,⑳商品別1食労務費!$F$5:$F$124)+SUMIF(⑳商品別1食労務費!$C$5:$C$124,$W16,⑳商品別1食労務費!$F$5:$F$124) | AB16: =IF(ISNUMBER($M16),$M16,0) | AD16: =IF($R16="",0,IF($AA16>0,$AB16*SUMIF(⑳商品別1食労務費!$C$5:$C$124,$R16,⑳商品別1食労務費!$F$5:$F$124)/$AA16,$AB16/$X16)) | AE16: =IF($S16="",0,IF($AA16>0,$AB16*SUMIF(⑳商品別1食労務費!$C$5:$C$124,$S16,⑳商品別1食労務費!$F$5:$F$124)/$AA16,$AB16/$X16)) | AF16: =IF($T16="",0,IF($AA16>0,$AB16*SUMIF(⑳商品別1食労務費!$C$5:$C$124,$T16,⑳商品別1食労務費!$F$5:$F$124)/$AA16,$AB16/$X16)) | AG16: =IF($U16="",0,IF($AA16>0,$AB16*SUMIF(⑳商品別1食労務費!$C$5:$C$124,$U16,⑳商品別1食労務費!$F$5:$F$124)/$AA16,$AB16/$X16)) | AH16: =IF($V16="",0,IF($AA16>0,$AB16*SUMIF(⑳商品別1食労務費!$C$5:$C$124,$V16,⑳商品別1食労務費!$F$5:$F$124)/$AA16,$AB16/$X16)) | AI16: =IF($W16="",0,IF($AA16>0,$AB16*SUMIF(⑳商品別1食労務費!$C$5:$C$124,$W16,⑳商品別1食労務費!$F$5:$F$124)/$AA16,$AB16/$X16))
A17: 13 | B17: 釜製造 | C17: 自社製ホイップの卵プリン | F17: 110 | G17: 90 | H17: 2 | I17: 120 | K17: - | L17: =IF(AND(ISNUMBER(F17),J17>0),J17/(F17/60),"") | M17: =IF(OR(ISNUMBER(SEARCH("サニテーション",C17)),ISNUMBER(SEARCH("客注",C17)),ISNUMBER(SEARCH("切り替え",C17)),ISNUMBER(SEARCH("切替",C17)),NOT(ISNUMBER(H17))),"",IF(ISNUMBER(G17),G17/60*H17*④前提設定!$B$4,IF(AND(G17="",ISNUMBER(F17)),F17/60*H17*④前提設定!$B$4,""))) | N17: - | O17: =IF(AND(J17>0,ISNUMBER(M17)),M17/J17,"") | R17: 自社製ホイップの卵プリン | S17: Ｓホイップの卵プリン | T17: ホイップの卵プリン | X17: =COUNTA(R17:W17) | Y17: =IF(AND($X17>0,ISNUMBER($M17)),$M17/$X17,"") | Z17: =IF($X17=0,"",IF(COUNTIF(⑳商品別1食労務費!$C$5:$C$124,$R17)+COUNTIF(⑳商品別1食労務費!$C$5:$C$124,$S17)+COUNTIF(⑳商品別1食労務費!$C$5:$C$124,$T17)+COUNTIF(⑳商品別1食労務費!$C$5:$C$124,$U17)+COUNTIF(⑳商品別1食労務費!$C$5:$C$124,$V17)+COUNTIF(⑳商品別1食労務費!$C$5:$C$124,$W17)=$X17,"OK","⑳に無い商品名")) | AA17: =SUMIF(⑳商品別1食労務費!$C$5:$C$124,$R17,⑳商品別1食労務費!$F$5:$F$124)+SUMIF(⑳商品別1食労務費!$C$5:$C$124,$S17,⑳商品別1食労務費!$F$5:$F$124)+SUMIF(⑳商品別1食労務費!$C$5:$C$124,$T17,⑳商品別1食労務費!$F$5:$F$124)+SUMIF(⑳商品別1食労務費!$C$5:$C$124,$U17,⑳商品別1食労務費!$F$5:$F$124)+SUMIF(⑳商品別1食労務費!$C$5:$C$124,$V17,⑳商品別1食労務費!$F$5:$F$124)+SUMIF(⑳商品別1食労務費!$C$5:$C$124,$W17,⑳商品別1食労務費!$F$5:$F$124) | AB17: =IF(ISNUMBER($M17),$M17,0) | AD17: =IF($R17="",0,IF($AA17>0,$AB17*SUMIF(⑳商品別1食労務費!$C$5:$C$124,$R17,⑳商品別1食労務費!$F$5:$F$124)/$AA17,$AB17/$X17)) | AE17: =IF($S17="",0,IF($AA17>0,$AB17*SUMIF(⑳商品別1食労務費!$C$5:$C$124,$S17,⑳商品別1食労務費!$F$5:$F$124)/$AA17,$AB17/$X17)) | AF17: =IF($T17="",0,IF($AA17>0,$AB17*SUMIF(⑳商品別1食労務費!$C$5:$C$124,$T17,⑳商品別1食労務費!$F$5:$F$124)/$AA17,$AB17/$X17)) | AG17: =IF($U17="",0,IF($AA17>0,$AB17*SUMIF(⑳商品別1食労務費!$C$5:$C$124,$U17,⑳商品別1食労務費!$F$5:$F$124)/$AA17,$AB17/$X17)) | AH17: =IF($V17="",0,IF($AA17>0,$AB17*SUMIF(⑳商品別1食労務費!$C$5:$C$124,$V17,⑳商品別1食労務費!$F$5:$F$124)/$AA17,$AB17/$X17)) | AI17: =IF($W17="",0,IF($AA17>0,$AB17*SUMIF(⑳商品別1食労務費!$C$5:$C$124,$W17,⑳商品別1食労務費!$F$5:$F$124)/$AA17,$AB17/$X17))
A18: 14 | B18: 釜製造 | C18: 自社製ホイップの卵プリン | F18: 110 | G18: 90 | H18: 2 | I18: 120 | K18: =IF(F18>0,I18/(F18/60),0) | L18: =IF(AND(ISNUMBER(F18),J18>0),J18/(F18/60),"") | M18: =IF(OR(ISNUMBER(SEARCH("サニテーション",C18)),ISNUMBER(SEARCH("客注",C18)),ISNUMBER(SEARCH("切り替え",C18)),ISNUMBER(SEARCH("切替",C18)),NOT(ISNUMBER(H18))),"",IF(ISNUMBER(G18),G18/60*H18*④前提設定!$B$4,IF(AND(G18="",ISNUMBER(F18)),F18/60*H18*④前提設定!$B$4,""))) | N18: =IF(I18>0,M18/I18,"") | O18: =IF(AND(J18>0,ISNUMBER(M18)),M18/J18,"") | R18: 自社製ホイップの卵プリン | S18: Ｓホイップの卵プリン | T18: ホイップの卵プリン | X18: =COUNTA(R18:W18) | Y18: =IF(AND($X18>0,ISNUMBER($M18)),$M18/$X18,"") | Z18: =IF($X18=0,"",IF(COUNTIF(⑳商品別1食労務費!$C$5:$C$124,$R18)+COUNTIF(⑳商品別1食労務費!$C$5:$C$124,$S18)+COUNTIF(⑳商品別1食労務費!$C$5:$C$124,$T18)+COUNTIF(⑳商品別1食労務費!$C$5:$C$124,$U18)+COUNTIF(⑳商品別1食労務費!$C$5:$C$124,$V18)+COUNTIF(⑳商品別1食労務費!$C$5:$C$124,$W18)=$X18,"OK","⑳に無い商品名")) | AA18: =SUMIF(⑳商品別1食労務費!$C$5:$C$124,$R18,⑳商品別1食労務費!$F$5:$F$124)+SUMIF(⑳商品別1食労務費!$C$5:$C$124,$S18,⑳商品別1食労務費!$F$5:$F$124)+SUMIF(⑳商品別1食労務費!$C$5:$C$124,$T18,⑳商品別1食労務費!$F$5:$F$124)+SUMIF(⑳商品別1食労務費!$C$5:$C$124,$U18,⑳商品別1食労務費!$F$5:$F$124)+SUMIF(⑳商品別1食労務費!$C$5:$C$124,$V18,⑳商品別1食労務費!$F$5:$F$124)+SUMIF(⑳商品別1食労務費!$C$5:$C$124,$W18,⑳商品別1食労務費!$F$5:$F$124) | AB18: =IF(ISNUMBER($M18),$M18,0) | AD18: =IF($R18="",0,IF($AA18>0,$AB18*SUMIF(⑳商品別1食労務費!$C$5:$C$124,$R18,⑳商品別1食労務費!$F$5:$F$124)/$AA18,$AB18/$X18)) | AE18: =IF($S18="",0,IF($AA18>0,$AB18*SUMIF(⑳商品別1食労務費!$C$5:$C$124,$S18,⑳商品別1食労務費!$F$5:$F$124)/$AA18,$AB18/$X18)) | AF18: =IF($T18="",0,IF($AA18>0,$AB18*SUMIF(⑳商品別1食労務費!$C$5:$C$124,$T18,⑳商品別1食労務費!$F$5:$F$124)/$AA18,$AB18/$X18)) | AG18: =IF($U18="",0,IF($AA18>0,$AB18*SUMIF(⑳商品別1食労務費!$C$5:$C$124,$U18,⑳商品別1食労務費!$F$5:$F$124)/$AA18,$AB18/$X18)) | AH18: =IF($V18="",0,IF($AA18>0,$AB18*SUMIF(⑳商品別1食労務費!$C$5:$C$124,$V18,⑳商品別1食労務費!$F$5:$F$124)/$AA18,$AB18/$X18)) | AI18: =IF($W18="",0,IF($AA18>0,$AB18*SUMIF(⑳商品別1食労務費!$C$5:$C$124,$W18,⑳商品別1食労務費!$F$5:$F$124)/$AA18,$AB18/$X18))
A19: 15 | B19: 釜製造 | C19: ミキサー | K19: =IF(F19>0,I19/(F19/60),0) | L19: =IF(AND(ISNUMBER(F19),J19>0),J19/(F19/60),"") | M19: =IF(OR(ISNUMBER(SEARCH("サニテーション",C19)),ISNUMBER(SEARCH("客注",C19)),ISNUMBER(SEARCH("切り替え",C19)),ISNUMBER(SEARCH("切替",C19)),NOT(ISNUMBER(H19))),"",IF(ISNUMBER(G19),G19/60*H19*④前提設定!$B$4,IF(AND(G19="",ISNUMBER(F19)),F19/60*H19*④前提設定!$B$4,""))) | N19: =IF(I19>0,M19/I19,"") | O19: =IF(AND(J19>0,ISNUMBER(M19)),M19/J19,"") | X19: =COUNTA(R19:W19) | Y19: =IF(AND($X19>0,ISNUMBER($M19)),$M19/$X19,"") | Z19: =IF($X19=0,"",IF(COUNTIF(⑳商品別1食労務費!$C$5:$C$124,$R19)+COUNTIF(⑳商品別1食労務費!$C$5:$C$124,$S19)+COUNTIF(⑳商品別1食労務費!$C$5:$C$124,$T19)+COUNTIF(⑳商品別1食労務費!$C$5:$C$124,$U19)+COUNTIF(⑳商品別1食労務費!$C$5:$C$124,$V19)+COUNTIF(⑳商品別1食労務費!$C$5:$C$124,$W19)=$X19,"OK","⑳に無い商品名")) | AA19: =SUMIF(⑳商品別1食労務費!$C$5:$C$124,$R19,⑳商品別1食労務費!$F$5:$F$124)+SUMIF(⑳商品別1食労務費!$C$5:$C$124,$S19,⑳商品別1食労務費!$F$5:$F$124)+SUMIF(⑳商品別1食労務費!$C$5:$C$124,$T19,⑳商品別1食労務費!$F$5:$F$124)+SUMIF(⑳商品別1食労務費!$C$5:$C$124,$U19,⑳商品別1食労務費!$F$5:$F$124)+SUMIF(⑳商品別1食労務費!$C$5:$C$124,$V19,⑳商品別1食労務費!$F$5:$F$124)+SUMIF(⑳商品別1食労務費!$C$5:$C$124,$W19,⑳商品別1食労務費!$F$5:$F$124) | AB19: =IF(ISNUMBER($M19),$M19,0) | AD19: =IF($R19="",0,IF($AA19>0,$AB19*SUMIF(⑳商品別1食労務費!$C$5:$C$124,$R19,⑳商品別1食労務費!$F$5:$F$124)/$AA19,$AB19/$X19)) | AE19: =IF($S19="",0,IF($AA19>0,$AB19*SUMIF(⑳商品別1食労務費!$C$5:$C$124,$S19,⑳商品別1食労務費!$F$5:$F$124)/$AA19,$AB19/$X19)) | AF19: =IF($T19="",0,IF($AA19>0,$AB19*SUMIF(⑳商品別1食労務費!$C$5:$C$124,$T19,⑳商品別1食労務費!$F$5:$F$124)/$AA19,$AB19/$X19)) | AG19: =IF($U19="",0,IF($AA19>0,$AB19*SUMIF(⑳商品別1食労務費!$C$5:$C$124,$U19,⑳商品別1食労務費!$F$5:$F$124)/$AA19,$AB19/$X19)) | AH19: =IF($V19="",0,IF($AA19>0,$AB19*SUMIF(⑳商品別1食労務費!$C$5:$C$124,$V19,⑳商品別1食労務費!$F$5:$F$124)/$AA19,$AB19/$X19)) | AI19: =IF($W19="",0,IF($AA19>0,$AB19*SUMIF(⑳商品別1食労務費!$C$5:$C$124,$W19,⑳商品別1食労務費!$F$5:$F$124)/$AA19,$AB19/$X19))
A20: 16 | B20: 釜製造 | C20: 湯種ロールパン | D20: 0.025 | E20: 0.038888889 | F20: 5 | G20: 15 | H20: 1 | I20: 16 | K20: =IF(F20>0,I20/(F20/60),0) | L20: =IF(AND(ISNUMBER(F20),J20>0),J20/(F20/60),"") | M20: =IF(OR(ISNUMBER(SEARCH("サニテーション",C20)),ISNUMBER(SEARCH("客注",C20)),ISNUMBER(SEARCH("切り替え",C20)),ISNUMBER(SEARCH("切替",C20)),NOT(ISNUMBER(H20))),"",IF(ISNUMBER(G20),G20/60*H20*④前提設定!$B$4,IF(AND(G20="",ISNUMBER(F20)),F20/60*H20*④前提設定!$B$4,""))) | N20: =IF(I20>0,M20/I20,"") | O20: =IF(AND(J20>0,ISNUMBER(M20)),M20/J20,"") | R20: 全粒粉入り湯種ロール６個 | S20: 全粒粉入り湯種ロール３個 | T20: Ｓ全粒粉入り湯種ロール６個 | X20: =COUNTA(R20:W20) | Y20: =IF(AND($X20>0,ISNUMBER($M20)),$M20/$X20,"") | Z20: =IF($X20=0,"",IF(COUNTIF(⑳商品別1食労務費!$C$5:$C$124,$R20)+COUNTIF(⑳商品別1食労務費!$C$5:$C$124,$S20)+COUNTIF(⑳商品別1食労務費!$C$5:$C$124,$T20)+COUNTIF(⑳商品別1食労務費!$C$5:$C$124,$U20)+COUNTIF(⑳商品別1食労務費!$C$5:$C$124,$V20)+COUNTIF(⑳商品別1食労務費!$C$5:$C$124,$W20)=$X20,"OK","⑳に無い商品名")) | AA20: =SUMIF(⑳商品別1食労務費!$C$5:$C$124,$R20,⑳商品別1食労務費!$F$5:$F$124)+SUMIF(⑳商品別1食労務費!$C$5:$C$124,$S20,⑳商品別1食労務費!$F$5:$F$124)+SUMIF(⑳商品別1食労務費!$C$5:$C$124,$T20,⑳商品別1食労務費!$F$5:$F$124)+SUMIF(⑳商品別1食労務費!$C$5:$C$124,$U20,⑳商品別1食労務費!$F$5:$F$124)+SUMIF(⑳商品別1食労務費!$C$5:$C$124,$V20,⑳商品別1食労務費!$F$5:$F$124)+SUMIF(⑳商品別1食労務費!$C$5:$C$124,$W20,⑳商品別1食労務費!$F$5:$F$124) | AB20: =IF(ISNUMBER($M20),$M20,0) | AD20: =IF($R20="",0,IF($AA20>0,$AB20*SUMIF(⑳商品別1食労務費!$C$5:$C$124,$R20,⑳商品別1食労務費!$F$5:$F$124)/$AA20,$AB20/$X20)) | AE20: =IF($S20="",0,IF($AA20>0,$AB20*SUMIF(⑳商品別1食労務費!$C$5:$C$124,$S20,⑳商品別1食労務費!$F$5:$F$124)/$AA20,$AB20/$X20)) | AF20: =IF($T20="",0,IF($AA20>0,$AB20*SUMIF(⑳商品別1食労務費!$C$5:$C$124,$T20,⑳商品別1食労務費!$F$5:$F$124)/$AA20,$AB20/$X20)) | AG20: =IF($U20="",0,IF($AA20>0,$AB20*SUMIF(⑳商品別1食労務費!$C$5:$C$124,$U20,⑳商品別1食労務費!$F$5:$F$124)/$AA20,$AB20/$X20)) | AH20: =IF($V20="",0,IF($AA20>0,$AB20*SUMIF(⑳商品別1食労務費!$C$5:$C$124,$V20,⑳商品別1食労務費!$F$5:$F$124)/$AA20,$AB20/$X20)) | AI20: =IF($W20="",0,IF($AA20>0,$AB20*SUMIF(⑳商品別1食労務費!$C$5:$C$124,$W20,⑳商品別1食労務費!$F$5:$F$124)/$AA20,$AB20/$X20))
A21: 17 | B21: 釜製造 | C21: 湯種ロールパン | D21: 0.038888889 | E21: 0.052777778 | F21: 5 | G21: 15 | H21: 1 | I21: 16 | K21: =IF(F21>0,I21/(F21/60),0) | L21: =IF(AND(ISNUMBER(F21),J21>0),J21/(F21/60),"") | M21: =IF(OR(ISNUMBER(SEARCH("サニテーション",C21)),ISNUMBER(SEARCH("客注",C21)),ISNUMBER(SEARCH("切り替え",C21)),ISNUMBER(SEARCH("切替",C21)),NOT(ISNUMBER(H21))),"",IF(ISNUMBER(G21),G21/60*H21*④前提設定!$B$4,IF(AND(G21="",ISNUMBER(F21)),F21/60*H21*④前提設定!$B$4,""))) | N21: =IF(I21>0,M21/I21,"") | O21: =IF(AND(J21>0,ISNUMBER(M21)),M21/J21,"") | R21: 全粒粉入り湯種ロール６個 | S21: 全粒粉入り湯種ロール３個 | T21: Ｓ全粒粉入り湯種ロール６個 | X21: =COUNTA(R21:W21) | Y21: =IF(AND($X21>0,ISNUMBER($M21)),$M21/$X21,"") | Z21: =IF($X21=0,"",IF(COUNTIF(⑳商品別1食労務費!$C$5:$C$124,$R21)+COUNTIF(⑳商品別1食労務費!$C$5:$C$124,$S21)+COUNTIF(⑳商品別1食労務費!$C$5:$C$124,$T21)+COUNTIF(⑳商品別1食労務費!$C$5:$C$124,$U21)+COUNTIF(⑳商品別1食労務費!$C$5:$C$124,$V21)+COUNTIF(⑳商品別1食労務費!$C$5:$C$124,$W21)=$X21,"OK","⑳に無い商品名")) | AA21: =SUMIF(⑳商品別1食労務費!$C$5:$C$124,$R21,⑳商品別1食労務費!$F$5:$F$124)+SUMIF(⑳商品別1食労務費!$C$5:$C$124,$S21,⑳商品別1食労務費!$F$5:$F$124)+SUMIF(⑳商品別1食労務費!$C$5:$C$124,$T21,⑳商品別1食労務費!$F$5:$F$124)+SUMIF(⑳商品別1食労務費!$C$5:$C$124,$U21,⑳商品別1食労務費!$F$5:$F$124)+SUMIF(⑳商品別1食労務費!$C$5:$C$124,$V21,⑳商品別1食労務費!$F$5:$F$124)+SUMIF(⑳商品別1食労務費!$C$5:$C$124,$W21,⑳商品別1食労務費!$F$5:$F$124) | AB21: =IF(ISNUMBER($M21),$M21,0) | AD21: =IF($R21="",0,IF($AA21>0,$AB21*SUMIF(⑳商品別1食労務費!$C$5:$C$124,$R21,⑳商品別1食労務費!$F$5:$F$124)/$AA21,$AB21/$X21)) | AE21: =IF($S21="",0,IF($AA21>0,$AB21*SUMIF(⑳商品別1食労務費!$C$5:$C$124,$S21,⑳商品別1食労務費!$F$5:$F$124)/$AA21,$AB21/$X21)) | AF21: =IF($T21="",0,IF($AA21>0,$AB21*SUMIF(⑳商品別1食労務費!$C$5:$C$124,$T21,⑳商品別1食労務費!$F$5:$F$124)/$AA21,$AB21/$X21)) | AG21: =IF($U21="",0,IF($AA21>0,$AB21*SUMIF(⑳商品別1食労務費!$C$5:$C$124,$U21,⑳商品別1食労務費!$F$5:$F$124)/$AA21,$AB21/$X21)) | AH21: =IF($V21="",0,IF($AA21>0,$AB21*SUMIF(⑳商品別1食労務費!$C$5:$C$124,$V21,⑳商品別1食労務費!$F$5:$F$124)/$AA21,$AB21/$X21)) | AI21: =IF($W21="",0,IF($AA21>0,$AB21*SUMIF(⑳商品別1食労務費!$C$5:$C$124,$W21,⑳商品別1食労務費!$F$5:$F$124)/$AA21,$AB21/$X21))
A22: 18 | B22: 釜製造 | C22: 湯種ロールパン | D22: 0.052777778 | E22: 0.066666667 | F22: 5 | G22: 15 | H22: 1 | I22: 16 | K22: =IF(F22>0,I22/(F22/60),0) | L22: =IF(AND(ISNUMBER(F22),J22>0),J22/(F22/60),"") | M22: =IF(OR(ISNUMBER(SEARCH("サニテーション",C22)),ISNUMBER(SEARCH("客注",C22)),ISNUMBER(SEARCH("切り替え",C22)),ISNUMBER(SEARCH("切替",C22)),NOT(ISNUMBER(H22))),"",IF(ISNUMBER(G22),G22/60*H22*④前提設定!$B$4,IF(AND(G22="",ISNUMBER(F22)),F22/60*H22*④前提設定!$B$4,""))) | N22: =IF(I22>0,M22/I22,"") | O22: =IF(AND(J22>0,ISNUMBER(M22)),M22/J22,"") | R22: 全粒粉入り湯種ロール６個 | S22: 全粒粉入り湯種ロール３個 | T22: Ｓ全粒粉入り湯種ロール６個 | X22: =COUNTA(R22:W22) | Y22: =IF(AND($X22>0,ISNUMBER($M22)),$M22/$X22,"") | Z22: =IF($X22=0,"",IF(COUNTIF(⑳商品別1食労務費!$C$5:$C$124,$R22)+COUNTIF(⑳商品別1食労務費!$C$5:$C$124,$S22)+COUNTIF(⑳商品別1食労務費!$C$5:$C$124,$T22)+COUNTIF(⑳商品別1食労務費!$C$5:$C$124,$U22)+COUNTIF(⑳商品別1食労務費!$C$5:$C$124,$V22)+COUNTIF(⑳商品別1食労務費!$C$5:$C$124,$W22)=$X22,"OK","⑳に無い商品名")) | AA22: =SUMIF(⑳商品別1食労務費!$C$5:$C$124,$R22,⑳商品別1食労務費!$F$5:$F$124)+SUMIF(⑳商品別1食労務費!$C$5:$C$124,$S22,⑳商品別1食労務費!$F$5:$F$124)+SUMIF(⑳商品別1食労務費!$C$5:$C$124,$T22,⑳商品別1食労務費!$F$5:$F$124)+SUMIF(⑳商品別1食労務費!$C$5:$C$124,$U22,⑳商品別1食労務費!$F$5:$F$124)+SUMIF(⑳商品別1食労務費!$C$5:$C$124,$V22,⑳商品別1食労務費!$F$5:$F$124)+SUMIF(⑳商品別1食労務費!$C$5:$C$124,$W22,⑳商品別1食労務費!$F$5:$F$124) | AB22: =IF(ISNUMBER($M22),$M22,0) | AD22: =IF($R22="",0,IF($AA22>0,$AB22*SUMIF(⑳商品別1食労務費!$C$5:$C$124,$R22,⑳商品別1食労務費!$F$5:$F$124)/$AA22,$AB22/$X22)) | AE22: =IF($S22="",0,IF($AA22>0,$AB22*SUMIF(⑳商品別1食労務費!$C$5:$C$124,$S22,⑳商品別1食労務費!$F$5:$F$124)/$AA22,$AB22/$X22)) | AF22: =IF($T22="",0,IF($AA22>0,$AB22*SUMIF(⑳商品別1食労務費!$C$5:$C$124,$T22,⑳商品別1食労務費!$F$5:$F$124)/$AA22,$AB22/$X22)) | AG22: =IF($U22="",0,IF($AA22>0,$AB22*SUMIF(⑳商品別1食労務費!$C$5:$C$124,$U22,⑳商品別1食労務費!$F$5:$F$124)/$AA22,$AB22/$X22)) | AH22: =IF($V22="",0,IF($AA22>0,$AB22*SUMIF(⑳商品別1食労務費!$C$5:$C$124,$V22,⑳商品別1食労務費!$F$5:$F$124)/$AA22,$AB22/$X22)) | AI22: =IF($W22="",0,IF($AA22>0,$AB22*SUMIF(⑳商品別1食労務費!$C$5:$C$124,$W22,⑳商品別1食労務費!$F$5:$F$124)/$AA22,$AB22/$X22))
A23: 19 | B23: 釜製造 | C23: 湯種ロールパン | D23: 0.066666667 | E23: 0.080555556 | F23: 5 | G23: 15 | H23: 1 | I23: 16 | K23: =IF(F23>0,I23/(F23/60),0) | L23: =IF(AND(ISNUMBER(F23),J23>0),J23/(F23/60),"") | M23: =IF(OR(ISNUMBER(SEARCH("サニテーション",C23)),ISNUMBER(SEARCH("客注",C23)),ISNUMBER(SEARCH("切り替え",C23)),ISNUMBER(SEARCH("切替",C23)),NOT(ISNUMBER(H23))),"",IF(ISNUMBER(G23),G23/60*H23*④前提設定!$B$4,IF(AND(G23="",ISNUMBER(F23)),F23/60*H23*④前提設定!$B$4,""))) | N23: =IF(I23>0,M23/I23,"") | O23: =IF(AND(J23>0,ISNUMBER(M23)),M23/J23,"") | R23: 全粒粉入り湯種ロール６個 | S23: 全粒粉入り湯種ロール３個 | T23: Ｓ全粒粉入り湯種ロール６個 | X23: =COUNTA(R23:W23) | Y23: =IF(AND($X23>0,ISNUMBER($M23)),$M23/$X23,"") | Z23: =IF($X23=0,"",IF(COUNTIF(⑳商品別1食労務費!$C$5:$C$124,$R23)+COUNTIF(⑳商品別1食労務費!$C$5:$C$124,$S23)+COUNTIF(⑳商品別1食労務費!$C$5:$C$124,$T23)+COUNTIF(⑳商品別1食労務費!$C$5:$C$124,$U23)+COUNTIF(⑳商品別1食労務費!$C$5:$C$124,$V23)+COUNTIF(⑳商品別1食労務費!$C$5:$C$124,$W23)=$X23,"OK","⑳に無い商品名")) | AA23: =SUMIF(⑳商品別1食労務費!$C$5:$C$124,$R23,⑳商品別1食労務費!$F$5:$F$124)+SUMIF(⑳商品別1食労務費!$C$5:$C$124,$S23,⑳商品別1食労務費!$F$5:$F$124)+SUMIF(⑳商品別1食労務費!$C$5:$C$124,$T23,⑳商品別1食労務費!$F$5:$F$124)+SUMIF(⑳商品別1食労務費!$C$5:$C$124,$U23,⑳商品別1食労務費!$F$5:$F$124)+SUMIF(⑳商品別1食労務費!$C$5:$C$124,$V23,⑳商品別1食労務費!$F$5:$F$124)+SUMIF(⑳商品別1食労務費!$C$5:$C$124,$W23,⑳商品別1食労務費!$F$5:$F$124) | AB23: =IF(ISNUMBER($M23),$M23,0) | AD23: =IF($R23="",0,IF($AA23>0,$AB23*SUMIF(⑳商品別1食労務費!$C$5:$C$124,$R23,⑳商品別1食労務費!$F$5:$F$124)/$AA23,$AB23/$X23)) | AE23: =IF($S23="",0,IF($AA23>0,$AB23*SUMIF(⑳商品別1食労務費!$C$5:$C$124,$S23,⑳商品別1食労務費!$F$5:$F$124)/$AA23,$AB23/$X23)) | AF23: =IF($T23="",0,IF($AA23>0,$AB23*SUMIF(⑳商品別1食労務費!$C$5:$C$124,$T23,⑳商品別1食労務費!$F$5:$F$124)/$AA23,$AB23/$X23)) | AG23: =IF($U23="",0,IF($AA23>0,$AB23*SUMIF(⑳商品別1食労務費!$C$5:$C$124,$U23,⑳商品別1食労務費!$F$5:$F$124)/$AA23,$AB23/$X23)) | AH23: =IF($V23="",0,IF($AA23>0,$AB23*SUMIF(⑳商品別1食労務費!$C$5:$C$124,$V23,⑳商品別1食労務費!$F$5:$F$124)/$AA23,$AB23/$X23)) | AI23: =IF($W23="",0,IF($AA23>0,$AB23*SUMIF(⑳商品別1食労務費!$C$5:$C$124,$W23,⑳商品別1食労務費!$F$5:$F$124)/$AA23,$AB23/$X23))
A24: 20 | B24: 釜製造 | C24: 湯種ロールパン | D24: 0.080555556 | E24: 0.094444444 | F24: 5 | G24: 15 | H24: 1 | I24: 16 | K24: =IF(F24>0,I24/(F24/60),0) | L24: =IF(AND(ISNUMBER(F24),J24>0),J24/(F24/60),"") | M24: =IF(OR(ISNUMBER(SEARCH("サニテーション",C24)),ISNUMBER(SEARCH("客注",C24)),ISNUMBER(SEARCH("切り替え",C24)),ISNUMBER(SEARCH("切替",C24)),NOT(ISNUMBER(H24))),"",IF(ISNUMBER(G24),G24/60*H24*④前提設定!$B$4,IF(AND(G24="",ISNUMBER(F24)),F24/60*H24*④前提設定!$B$4,""))) | N24: =IF(I24>0,M24/I24,"") | O24: =IF(AND(J24>0,ISNUMBER(M24)),M24/J24,"") | R24: 全粒粉入り湯種ロール６個 | S24: 全粒粉入り湯種ロール３個 | T24: Ｓ全粒粉入り湯種ロール６個 | X24: =COUNTA(R24:W24) | Y24: =IF(AND($X24>0,ISNUMBER($M24)),$M24/$X24,"") | Z24: =IF($X24=0,"",IF(COUNTIF(⑳商品別1食労務費!$C$5:$C$124,$R24)+COUNTIF(⑳商品別1食労務費!$C$5:$C$124,$S24)+COUNTIF(⑳商品別1食労務費!$C$5:$C$124,$T24)+COUNTIF(⑳商品別1食労務費!$C$5:$C$124,$U24)+COUNTIF(⑳商品別1食労務費!$C$5:$C$124,$V24)+COUNTIF(⑳商品別1食労務費!$C$5:$C$124,$W24)=$X24,"OK","⑳に無い商品名")) | AA24: =SUMIF(⑳商品別1食労務費!$C$5:$C$124,$R24,⑳商品別1食労務費!$F$5:$F$124)+SUMIF(⑳商品別1食労務費!$C$5:$C$124,$S24,⑳商品別1食労務費!$F$5:$F$124)+SUMIF(⑳商品別1食労務費!$C$5:$C$124,$T24,⑳商品別1食労務費!$F$5:$F$124)+SUMIF(⑳商品別1食労務費!$C$5:$C$124,$U24,⑳商品別1食労務費!$F$5:$F$124)+SUMIF(⑳商品別1食労務費!$C$5:$C$124,$V24,⑳商品別1食労務費!$F$5:$F$124)+SUMIF(⑳商品別1食労務費!$C$5:$C$124,$W24,⑳商品別1食労務費!$F$5:$F$124) | AB24: =IF(ISNUMBER($M24),$M24,0) | AD24: =IF($R24="",0,IF($AA24>0,$AB24*SUMIF(⑳商品別1食労務費!$C$5:$C$124,$R24,⑳商品別1食労務費!$F$5:$F$124)/$AA24,$AB24/$X24)) | AE24: =IF($S24="",0,IF($AA24>0,$AB24*SUMIF(⑳商品別1食労務費!$C$5:$C$124,$S24,⑳商品別1食労務費!$F$5:$F$124)/$AA24,$AB24/$X24)) | AF24: =IF($T24="",0,IF($AA24>0,$AB24*SUMIF(⑳商品別1食労務費!$C$5:$C$124,$T24,⑳商品別1食労務費!$F$5:$F$124)/$AA24,$AB24/$X24)) | AG24: =IF($U24="",0,IF($AA24>0,$AB24*SUMIF(⑳商品別1食労務費!$C$5:$C$124,$U24,⑳商品別1食労務費!$F$5:$F$124)/$AA24,$AB24/$X24)) | AH24: =IF($V24="",0,IF($AA24>0,$AB24*SUMIF(⑳商品別1食労務費!$C$5:$C$124,$V24,⑳商品別1食労務費!$F$5:$F$124)/$AA24,$AB24/$X24)) | AI24: =IF($W24="",0,IF($AA24>0,$AB24*SUMIF(⑳商品別1食労務費!$C$5:$C$124,$W24,⑳商品別1食労務費!$F$5:$F$124)/$AA24,$AB24/$X24))
A25: 21 | B25: 釜製造 | C25: ホテルロール | D25: 0.094444444 | E25: 0.10833333 | F25: 5 | G25: 15 | H25: 1 | I25: 16 | K25: =IF(F25>0,I25/(F25/60),0) | L25: =IF(AND(ISNUMBER(F25),J25>0),J25/(F25/60),"") | M25: =IF(OR(ISNUMBER(SEARCH("サニテーション",C25)),ISNUMBER(SEARCH("客注",C25)),ISNUMBER(SEARCH("切り替え",C25)),ISNUMBER(SEARCH("切替",C25)),NOT(ISNUMBER(H25))),"",IF(ISNUMBER(G25),G25/60*H25*④前提設定!$B$4,IF(AND(G25="",ISNUMBER(F25)),F25/60*H25*④前提設定!$B$4,""))) | N25: =IF(I25>0,M25/I25,"") | O25: =IF(AND(J25>0,ISNUMBER(M25)),M25/J25,"") | R25: ふわもちホテルロール３個 | S25: ふわもちホテルロール８個入 | T25: ふわもちホテルロール１６個 | U25: Ｓふわもちホテルロール８個 | V25: Ｓふわもちホテルロール１６ | W25: ホテルロールＫＩＴ ４０個 | X25: =COUNTA(R25:W25) | Y25: =IF(AND($X25>0,ISNUMBER($M25)),$M25/$X25,"") | Z25: =IF($X25=0,"",IF(COUNTIF(⑳商品別1食労務費!$C$5:$C$124,$R25)+COUNTIF(⑳商品別1食労務費!$C$5:$C$124,$S25)+COUNTIF(⑳商品別1食労務費!$C$5:$C$124,$T25)+COUNTIF(⑳商品別1食労務費!$C$5:$C$124,$U25)+COUNTIF(⑳商品別1食労務費!$C$5:$C$124,$V25)+COUNTIF(⑳商品別1食労務費!$C$5:$C$124,$W25)=$X25,"OK","⑳に無い商品名")) | AA25: =SUMIF(⑳商品別1食労務費!$C$5:$C$124,$R25,⑳商品別1食労務費!$F$5:$F$124)+SUMIF(⑳商品別1食労務費!$C$5:$C$124,$S25,⑳商品別1食労務費!$F$5:$F$124)+SUMIF(⑳商品別1食労務費!$C$5:$C$124,$T25,⑳商品別1食労務費!$F$5:$F$124)+SUMIF(⑳商品別1食労務費!$C$5:$C$124,$U25,⑳商品別1食労務費!$F$5:$F$124)+SUMIF(⑳商品別1食労務費!$C$5:$C$124,$V25,⑳商品別1食労務費!$F$5:$F$124)+SUMIF(⑳商品別1食労務費!$C$5:$C$124,$W25,⑳商品別1食労務費!$F$5:$F$124) | AB25: =IF(ISNUMBER($M25),$M25,0) | AD25: =IF($R25="",0,IF($AA25>0,$AB25*SUMIF(⑳商品別1食労務費!$C$5:$C$124,$R25,⑳商品別1食労務費!$F$5:$F$124)/$AA25,$AB25/$X25)) | AE25: =IF($S25="",0,IF($AA25>0,$AB25*SUMIF(⑳商品別1食労務費!$C$5:$C$124,$S25,⑳商品別1食労務費!$F$5:$F$124)/$AA25,$AB25/$X25)) | AF25: =IF($T25="",0,IF($AA25>0,$AB25*SUMIF(⑳商品別1食労務費!$C$5:$C$124,$T25,⑳商品別1食労務費!$F$5:$F$124)/$AA25,$AB25/$X25)) | AG25: =IF($U25="",0,IF($AA25>0,$AB25*SUMIF(⑳商品別1食労務費!$C$5:$C$124,$U25,⑳商品別1食労務費!$F$5:$F$124)/$AA25,$AB25/$X25)) | AH25: =IF($V25="",0,IF($AA25>0,$AB25*SUMIF(⑳商品別1食労務費!$C$5:$C$124,$V25,⑳商品別1食労務費!$F$5:$F$124)/$AA25,$AB25/$X25)) | AI25: =IF($W25="",0,IF($AA25>0,$AB25*SUMIF(⑳商品別1食労務費!$C$5:$C$124,$W25,⑳商品別1食労務費!$F$5:$F$124)/$AA25,$AB25/$X25))
A26: 22 | B26: 釜製造 | C26: ホテルロール | D26: 0.10833333 | E26: 0.12222222 | F26: 5 | G26: 15 | H26: 1 | I26: 16 | K26: =IF(F26>0,I26/(F26/60),0) | L26: =IF(AND(ISNUMBER(F26),J26>0),J26/(F26/60),"") | M26: =IF(OR(ISNUMBER(SEARCH("サニテーション",C26)),ISNUMBER(SEARCH("客注",C26)),ISNUMBER(SEARCH("切り替え",C26)),ISNUMBER(SEARCH("切替",C26)),NOT(ISNUMBER(H26))),"",IF(ISNUMBER(G26),G26/60*H26*④前提設定!$B$4,IF(AND(G26="",ISNUMBER(F26)),F26/60*H26*④前提設定!$B$4,""))) | N26: =IF(I26>0,M26/I26,"") | O26: =IF(AND(J26>0,ISNUMBER(M26)),M26/J26,"") | R26: ふわもちホテルロール３個 | S26: ふわもちホテルロール８個入 | T26: ふわもちホテルロール１６個 | U26: Ｓふわもちホテルロール８個 | V26: Ｓふわもちホテルロール１６ | W26: ホテルロールＫＩＴ ４０個 | X26: =COUNTA(R26:W26) | Y26: =IF(AND($X26>0,ISNUMBER($M26)),$M26/$X26,"") | Z26: =IF($X26=0,"",IF(COUNTIF(⑳商品別1食労務費!$C$5:$C$124,$R26)+COUNTIF(⑳商品別1食労務費!$C$5:$C$124,$S26)+COUNTIF(⑳商品別1食労務費!$C$5:$C$124,$T26)+COUNTIF(⑳商品別1食労務費!$C$5:$C$124,$U26)+COUNTIF(⑳商品別1食労務費!$C$5:$C$124,$V26)+COUNTIF(⑳商品別1食労務費!$C$5:$C$124,$W26)=$X26,"OK","⑳に無い商品名")) | AA26: =SUMIF(⑳商品別1食労務費!$C$5:$C$124,$R26,⑳商品別1食労務費!$F$5:$F$124)+SUMIF(⑳商品別1食労務費!$C$5:$C$124,$S26,⑳商品別1食労務費!$F$5:$F$124)+SUMIF(⑳商品別1食労務費!$C$5:$C$124,$T26,⑳商品別1食労務費!$F$5:$F$124)+SUMIF(⑳商品別1食労務費!$C$5:$C$124,$U26,⑳商品別1食労務費!$F$5:$F$124)+SUMIF(⑳商品別1食労務費!$C$5:$C$124,$V26,⑳商品別1食労務費!$F$5:$F$124)+SUMIF(⑳商品別1食労務費!$C$5:$C$124,$W26,⑳商品別1食労務費!$F$5:$F$124) | AB26: =IF(ISNUMBER($M26),$M26,0) | AD26: =IF($R26="",0,IF($AA26>0,$AB26*SUMIF(⑳商品別1食労務費!$C$5:$C$124,$R26,⑳商品別1食労務費!$F$5:$F$124)/$AA26,$AB26/$X26)) | AE26: =IF($S26="",0,IF($AA26>0,$AB26*SUMIF(⑳商品別1食労務費!$C$5:$C$124,$S26,⑳商品別1食労務費!$F$5:$F$124)/$AA26,$AB26/$X26)) | AF26: =IF($T26="",0,IF($AA26>0,$AB26*SUMIF(⑳商品別1食労務費!$C$5:$C$124,$T26,⑳商品別1食労務費!$F$5:$F$124)/$AA26,$AB26/$X26)) | AG26: =IF($U26="",0,IF($AA26>0,$AB26*SUMIF(⑳商品別1食労務費!$C$5:$C$124,$U26,⑳商品別1食労務費!$F$5:$F$124)/$AA26,$AB26/$X26)) | AH26: =IF($V26="",0,IF($AA26>0,$AB26*SUMIF(⑳商品別1食労務費!$C$5:$C$124,$V26,⑳商品別1食労務費!$F$5:$F$124)/$AA26,$AB26/$X26)) | AI26: =IF($W26="",0,IF($AA26>0,$AB26*SUMIF(⑳商品別1食労務費!$C$5:$C$124,$W26,⑳商品別1食労務費!$F$5:$F$124)/$AA26,$AB26/$X26))
A27: 23 | B27: 釜製造 | C27: ホテルロール | D27: 0.12222222 | E27: 0.13611111 | F27: 5 | G27: 15 | H27: 1 | I27: 16 | K27: - | L27: =IF(AND(ISNUMBER(F27),J27>0),J27/(F27/60),"") | M27: =IF(OR(ISNUMBER(SEARCH("サニテーション",C27)),ISNUMBER(SEARCH("客注",C27)),ISNUMBER(SEARCH("切り替え",C27)),ISNUMBER(SEARCH("切替",C27)),NOT(ISNUMBER(H27))),"",IF(ISNUMBER(G27),G27/60*H27*④前提設定!$B$4,IF(AND(G27="",ISNUMBER(F27)),F27/60*H27*④前提設定!$B$4,""))) | N27: - | O27: =IF(AND(J27>0,ISNUMBER(M27)),M27/J27,"") | R27: ふわもちホテルロール３個 | S27: ふわもちホテルロール８個入 | T27: ふわもちホテルロール１６個 | U27: Ｓふわもちホテルロール８個 | V27: Ｓふわもちホテルロール１６ | W27: ホテルロールＫＩＴ ４０個 | X27: =COUNTA(R27:W27) | Y27: =IF(AND($X27>0,ISNUMBER($M27)),$M27/$X27,"") | Z27: =IF($X27=0,"",IF(COUNTIF(⑳商品別1食労務費!$C$5:$C$124,$R27)+COUNTIF(⑳商品別1食労務費!$C$5:$C$124,$S27)+COUNTIF(⑳商品別1食労務費!$C$5:$C$124,$T27)+COUNTIF(⑳商品別1食労務費!$C$5:$C$124,$U27)+COUNTIF(⑳商品別1食労務費!$C$5:$C$124,$V27)+COUNTIF(⑳商品別1食労務費!$C$5:$C$124,$W27)=$X27,"OK","⑳に無い商品名")) | AA27: =SUMIF(⑳商品別1食労務費!$C$5:$C$124,$R27,⑳商品別1食労務費!$F$5:$F$124)+SUMIF(⑳商品別1食労務費!$C$5:$C$124,$S27,⑳商品別1食労務費!$F$5:$F$124)+SUMIF(⑳商品別1食労務費!$C$5:$C$124,$T27,⑳商品別1食労務費!$F$5:$F$124)+SUMIF(⑳商品別1食労務費!$C$5:$C$124,$U27,⑳商品別1食労務費!$F$5:$F$124)+SUMIF(⑳商品別1食労務費!$C$5:$C$124,$V27,⑳商品別1食労務費!$F$5:$F$124)+SUMIF(⑳商品別1食労務費!$C$5:$C$124,$W27,⑳商品別1食労務費!$F$5:$F$124) | AB27: =IF(ISNUMBER($M27),$M27,0) | AD27: =IF($R27="",0,IF($AA27>0,$AB27*SUMIF(⑳商品別1食労務費!$C$5:$C$124,$R27,⑳商品別1食労務費!$F$5:$F$124)/$AA27,$AB27/$X27)) | AE27: =IF($S27="",0,IF($AA27>0,$AB27*SUMIF(⑳商品別1食労務費!$C$5:$C$124,$S27,⑳商品別1食労務費!$F$5:$F$124)/$AA27,$AB27/$X27)) | AF27: =IF($T27="",0,IF($AA27>0,$AB27*SUMIF(⑳商品別1食労務費!$C$5:$C$124,$T27,⑳商品別1食労務費!$F$5:$F$124)/$AA27,$AB27/$X27)) | AG27: =IF($U27="",0,IF($AA27>0,$AB27*SUMIF(⑳商品別1食労務費!$C$5:$C$124,$U27,⑳商品別1食労務費!$F$5:$F$124)/$AA27,$AB27/$X27)) | AH27: =IF($V27="",0,IF($AA27>0,$AB27*SUMIF(⑳商品別1食労務費!$C$5:$C$124,$V27,⑳商品別1食労務費!$F$5:$F$124)/$AA27,$AB27/$X27)) | AI27: =IF($W27="",0,IF($AA27>0,$AB27*SUMIF(⑳商品別1食労務費!$C$5:$C$124,$W27,⑳商品別1食労務費!$F$5:$F$124)/$AA27,$AB27/$X27))
A28: 24 | B28: 釜製造 | C28: ホテルロール | D28: 0.13611111 | E28: 0.15 | F28: 5 | G28: 15 | H28: 1 | I28: 16 | K28: =IF(F28>0,I28/(F28/60),0) | L28: =IF(AND(ISNUMBER(F28),J28>0),J28/(F28/60),"") | M28: =IF(OR(ISNUMBER(SEARCH("サニテーション",C28)),ISNUMBER(SEARCH("客注",C28)),ISNUMBER(SEARCH("切り替え",C28)),ISNUMBER(SEARCH("切替",C28)),NOT(ISNUMBER(H28))),"",IF(ISNUMBER(G28),G28/60*H28*④前提設定!$B$4,IF(AND(G28="",ISNUMBER(F28)),F28/60*H28*④前提設定!$B$4,""))) | N28: =IF(I28>0,M28/I28,"") | O28: =IF(AND(J28>0,ISNUMBER(M28)),M28/J28,"") | R28: ふわもちホテルロール３個 | S28: ふわもちホテルロール８個入 | T28: ふわもちホテルロール１６個 | U28: Ｓふわもちホテルロール８個 | V28: Ｓふわもちホテルロール１６ | W28: ホテルロールＫＩＴ ４０個 | X28: =COUNTA(R28:W28) | Y28: =IF(AND($X28>0,ISNUMBER($M28)),$M28/$X28,"") | Z28: =IF($X28=0,"",IF(COUNTIF(⑳商品別1食労務費!$C$5:$C$124,$R28)+COUNTIF(⑳商品別1食労務費!$C$5:$C$124,$S28)+COUNTIF(⑳商品別1食労務費!$C$5:$C$124,$T28)+COUNTIF(⑳商品別1食労務費!$C$5:$C$124,$U28)+COUNTIF(⑳商品別1食労務費!$C$5:$C$124,$V28)+COUNTIF(⑳商品別1食労務費!$C$5:$C$124,$W28)=$X28,"OK","⑳に無い商品名")) | AA28: =SUMIF(⑳商品別1食労務費!$C$5:$C$124,$R28,⑳商品別1食労務費!$F$5:$F$124)+SUMIF(⑳商品別1食労務費!$C$5:$C$124,$S28,⑳商品別1食労務費!$F$5:$F$124)+SUMIF(⑳商品別1食労務費!$C$5:$C$124,$T28,⑳商品別1食労務費!$F$5:$F$124)+SUMIF(⑳商品別1食労務費!$C$5:$C$124,$U28,⑳商品別1食労務費!$F$5:$F$124)+SUMIF(⑳商品別1食労務費!$C$5:$C$124,$V28,⑳商品別1食労務費!$F$5:$F$124)+SUMIF(⑳商品別1食労務費!$C$5:$C$124,$W28,⑳商品別1食労務費!$F$5:$F$124) | AB28: =IF(ISNUMBER($M28),$M28,0) | AD28: =IF($R28="",0,IF($AA28>0,$AB28*SUMIF(⑳商品別1食労務費!$C$5:$C$124,$R28,⑳商品別1食労務費!$F$5:$F$124)/$AA28,$AB28/$X28)) | AE28: =IF($S28="",0,IF($AA28>0,$AB28*SUMIF(⑳商品別1食労務費!$C$5:$C$124,$S28,⑳商品別1食労務費!$F$5:$F$124)/$AA28,$AB28/$X28)) | AF28: =IF($T28="",0,IF($AA28>0,$AB28*SUMIF(⑳商品別1食労務費!$C$5:$C$124,$T28,⑳商品別1食労務費!$F$5:$F$124)/$AA28,$AB28/$X28)) | AG28: =IF($U28="",0,IF($AA28>0,$AB28*SUMIF(⑳商品別1食労務費!$C$5:$C$124,$U28,⑳商品別1食労務費!$F$5:$F$124)/$AA28,$AB28/$X28)) | AH28: =IF($V28="",0,IF($AA28>0,$AB28*SUMIF(⑳商品別1食労務費!$C$5:$C$124,$V28,⑳商品別1食労務費!$F$5:$F$124)/$AA28,$AB28/$X28)) | AI28: =IF($W28="",0,IF($AA28>0,$AB28*SUMIF(⑳商品別1食労務費!$C$5:$C$124,$W28,⑳商品別1食労務費!$F$5:$F$124)/$AA28,$AB28/$X28))
A29: 25 | B29: 釜製造 | C29: ホテルロール | D29: 0.15 | E29: 0.16388889 | F29: 5 | G29: 15 | H29: 1 | I29: 16 | K29: =IF(F29>0,I29/(F29/60),0) | L29: =IF(AND(ISNUMBER(F29),J29>0),J29/(F29/60),"") | M29: =IF(OR(ISNUMBER(SEARCH("サニテーション",C29)),ISNUMBER(SEARCH("客注",C29)),ISNUMBER(SEARCH("切り替え",C29)),ISNUMBER(SEARCH("切替",C29)),NOT(ISNUMBER(H29))),"",IF(ISNUMBER(G29),G29/60*H29*④前提設定!$B$4,IF(AND(G29="",ISNUMBER(F29)),F29/60*H29*④前提設定!$B$4,""))) | N29: =IF(I29>0,M29/I29,"") | O29: =IF(AND(J29>0,ISNUMBER(M29)),M29/J29,"") | R29: ふわもちホテルロール３個 | S29: ふわもちホテルロール８個入 | T29: ふわもちホテルロール１６個 | U29: Ｓふわもちホテルロール８個 | V29: Ｓふわもちホテルロール１６ | W29: ホテルロールＫＩＴ ４０個 | X29: =COUNTA(R29:W29) | Y29: =IF(AND($X29>0,ISNUMBER($M29)),$M29/$X29,"") | Z29: =IF($X29=0,"",IF(COUNTIF(⑳商品別1食労務費!$C$5:$C$124,$R29)+COUNTIF(⑳商品別1食労務費!$C$5:$C$124,$S29)+COUNTIF(⑳商品別1食労務費!$C$5:$C$124,$T29)+COUNTIF(⑳商品別1食労務費!$C$5:$C$124,$U29)+COUNTIF(⑳商品別1食労務費!$C$5:$C$124,$V29)+COUNTIF(⑳商品別1食労務費!$C$5:$C$124,$W29)=$X29,"OK","⑳に無い商品名")) | AA29: =SUMIF(⑳商品別1食労務費!$C$5:$C$124,$R29,⑳商品別1食労務費!$F$5:$F$124)+SUMIF(⑳商品別1食労務費!$C$5:$C$124,$S29,⑳商品別1食労務費!$F$5:$F$124)+SUMIF(⑳商品別1食労務費!$C$5:$C$124,$T29,⑳商品別1食労務費!$F$5:$F$124)+SUMIF(⑳商品別1食労務費!$C$5:$C$124,$U29,⑳商品別1食労務費!$F$5:$F$124)+SUMIF(⑳商品別1食労務費!$C$5:$C$124,$V29,⑳商品別1食労務費!$F$5:$F$124)+SUMIF(⑳商品別1食労務費!$C$5:$C$124,$W29,⑳商品別1食労務費!$F$5:$F$124) | AB29: =IF(ISNUMBER($M29),$M29,0) | AD29: =IF($R29="",0,IF($AA29>0,$AB29*SUMIF(⑳商品別1食労務費!$C$5:$C$124,$R29,⑳商品別1食労務費!$F$5:$F$124)/$AA29,$AB29/$X29)) | AE29: =IF($S29="",0,IF($AA29>0,$AB29*SUMIF(⑳商品別1食労務費!$C$5:$C$124,$S29,⑳商品別1食労務費!$F$5:$F$124)/$AA29,$AB29/$X29)) | AF29: =IF($T29="",0,IF($AA29>0,$AB29*SUMIF(⑳商品別1食労務費!$C$5:$C$124,$T29,⑳商品別1食労務費!$F$5:$F$124)/$AA29,$AB29/$X29)) | AG29: =IF($U29="",0,IF($AA29>0,$AB29*SUMIF(⑳商品別1食労務費!$C$5:$C$124,$U29,⑳商品別1食労務費!$F$5:$F$124)/$AA29,$AB29/$X29)) | AH29: =IF($V29="",0,IF($AA29>0,$AB29*SUMIF(⑳商品別1食労務費!$C$5:$C$124,$V29,⑳商品別1食労務費!$F$5:$F$124)/$AA29,$AB29/$X29)) | AI29: =IF($W29="",0,IF($AA29>0,$AB29*SUMIF(⑳商品別1食労務費!$C$5:$C$124,$W29,⑳商品別1食労務費!$F$5:$F$124)/$AA29,$AB29/$X29))
A30: 26 | B30: 釜製造 | C30: ホテルロール | D30: 0.16388889 | E30: 0.17777778 | F30: 5 | G30: 15 | H30: 1 | I30: 16 | K30: =IF(F30>0,I30/(F30/60),0) | L30: =IF(AND(ISNUMBER(F30),J30>0),J30/(F30/60),"") | M30: =IF(OR(ISNUMBER(SEARCH("サニテーション",C30)),ISNUMBER(SEARCH("客注",C30)),ISNUMBER(SEARCH("切り替え",C30)),ISNUMBER(SEARCH("切替",C30)),NOT(ISNUMBER(H30))),"",IF(ISNUMBER(G30),G30/60*H30*④前提設定!$B$4,IF(AND(G30="",ISNUMBER(F30)),F30/60*H30*④前提設定!$B$4,""))) | N30: =IF(I30>0,M30/I30,"") | O30: =IF(AND(J30>0,ISNUMBER(M30)),M30/J30,"") | R30: ふわもちホテルロール３個 | S30: ふわもちホテルロール８個入 | T30: ふわもちホテルロール１６個 | U30: Ｓふわもちホテルロール８個 | V30: Ｓふわもちホテルロール１６ | W30: ホテルロールＫＩＴ ４０個 | X30: =COUNTA(R30:W30) | Y30: =IF(AND($X30>0,ISNUMBER($M30)),$M30/$X30,"") | Z30: =IF($X30=0,"",IF(COUNTIF(⑳商品別1食労務費!$C$5:$C$124,$R30)+COUNTIF(⑳商品別1食労務費!$C$5:$C$124,$S30)+COUNTIF(⑳商品別1食労務費!$C$5:$C$124,$T30)+COUNTIF(⑳商品別1食労務費!$C$5:$C$124,$U30)+COUNTIF(⑳商品別1食労務費!$C$5:$C$124,$V30)+COUNTIF(⑳商品別1食労務費!$C$5:$C$124,$W30)=$X30,"OK","⑳に無い商品名")) | AA30: =SUMIF(⑳商品別1食労務費!$C$5:$C$124,$R30,⑳商品別1食労務費!$F$5:$F$124)+SUMIF(⑳商品別1食労務費!$C$5:$C$124,$S30,⑳商品別1食労務費!$F$5:$F$124)+SUMIF(⑳商品別1食労務費!$C$5:$C$124,$T30,⑳商品別1食労務費!$F$5:$F$124)+SUMIF(⑳商品別1食労務費!$C$5:$C$124,$U30,⑳商品別1食労務費!$F$5:$F$124)+SUMIF(⑳商品別1食労務費!$C$5:$C$124,$V30,⑳商品別1食労務費!$F$5:$F$124)+SUMIF(⑳商品別1食労務費!$C$5:$C$124,$W30,⑳商品別1食労務費!$F$5:$F$124) | AB30: =IF(ISNUMBER($M30),$M30,0) | AD30: =IF($R30="",0,IF($AA30>0,$AB30*SUMIF(⑳商品別1食労務費!$C$5:$C$124,$R30,⑳商品別1食労務費!$F$5:$F$124)/$AA30,$AB30/$X30)) | AE30: =IF($S30="",0,IF($AA30>0,$AB30*SUMIF(⑳商品別1食労務費!$C$5:$C$124,$S30,⑳商品別1食労務費!$F$5:$F$124)/$AA30,$AB30/$X30)) | AF30: =IF($T30="",0,IF($AA30>0,$AB30*SUMIF(⑳商品別1食労務費!$C$5:$C$124,$T30,⑳商品別1食労務費!$F$5:$F$124)/$AA30,$AB30/$X30)) | AG30: =IF($U30="",0,IF($AA30>0,$AB30*SUMIF(⑳商品別1食労務費!$C$5:$C$124,$U30,⑳商品別1食労務費!$F$5:$F$124)/$AA30,$AB30/$X30)) | AH30: =IF($V30="",0,IF($AA30>0,$AB30*SUMIF(⑳商品別1食労務費!$C$5:$C$124,$V30,⑳商品別1食労務費!$F$5:$F$124)/$AA30,$AB30/$X30)) | AI30: =IF($W30="",0,IF($AA30>0,$AB30*SUMIF(⑳商品別1食労務費!$C$5:$C$124,$W30,⑳商品別1食労務費!$F$5:$F$124)/$AA30,$AB30/$X30))
A31: 27 | B31: 釜製造 | C31: ホテルロール | D31: 0.17777778 | E31: 0.19166667 | F31: 5 | G31: 15 | H31: 1 | I31: 16 | K31: =IF(F31>0,I31/(F31/60),0) | L31: =IF(AND(ISNUMBER(F31),J31>0),J31/(F31/60),"") | M31: =IF(OR(ISNUMBER(SEARCH("サニテーション",C31)),ISNUMBER(SEARCH("客注",C31)),ISNUMBER(SEARCH("切り替え",C31)),ISNUMBER(SEARCH("切替",C31)),NOT(ISNUMBER(H31))),"",IF(ISNUMBER(G31),G31/60*H31*④前提設定!$B$4,IF(AND(G31="",ISNUMBER(F31)),F31/60*H31*④前提設定!$B$4,""))) | N31: =IF(I31>0,M31/I31,"") | O31: =IF(AND(J31>0,ISNUMBER(M31)),M31/J31,"") | R31: ふわもちホテルロール３個 | S31: ふわもちホテルロール８個入 | T31: ふわもちホテルロール１６個 | U31: Ｓふわもちホテルロール８個 | V31: Ｓふわもちホテルロール１６ | W31: ホテルロールＫＩＴ ４０個 | X31: =COUNTA(R31:W31) | Y31: =IF(AND($X31>0,ISNUMBER($M31)),$M31/$X31,"") | Z31: =IF($X31=0,"",IF(COUNTIF(⑳商品別1食労務費!$C$5:$C$124,$R31)+COUNTIF(⑳商品別1食労務費!$C$5:$C$124,$S31)+COUNTIF(⑳商品別1食労務費!$C$5:$C$124,$T31)+COUNTIF(⑳商品別1食労務費!$C$5:$C$124,$U31)+COUNTIF(⑳商品別1食労務費!$C$5:$C$124,$V31)+COUNTIF(⑳商品別1食労務費!$C$5:$C$124,$W31)=$X31,"OK","⑳に無い商品名")) | AA31: =SUMIF(⑳商品別1食労務費!$C$5:$C$124,$R31,⑳商品別1食労務費!$F$5:$F$124)+SUMIF(⑳商品別1食労務費!$C$5:$C$124,$S31,⑳商品別1食労務費!$F$5:$F$124)+SUMIF(⑳商品別1食労務費!$C$5:$C$124,$T31,⑳商品別1食労務費!$F$5:$F$124)+SUMIF(⑳商品別1食労務費!$C$5:$C$124,$U31,⑳商品別1食労務費!$F$5:$F$124)+SUMIF(⑳商品別1食労務費!$C$5:$C$124,$V31,⑳商品別1食労務費!$F$5:$F$124)+SUMIF(⑳商品別1食労務費!$C$5:$C$124,$W31,⑳商品別1食労務費!$F$5:$F$124) | AB31: =IF(ISNUMBER($M31),$M31,0) | AD31: =IF($R31="",0,IF($AA31>0,$AB31*SUMIF(⑳商品別1食労務費!$C$5:$C$124,$R31,⑳商品別1食労務費!$F$5:$F$124)/$AA31,$AB31/$X31)) | AE31: =IF($S31="",0,IF($AA31>0,$AB31*SUMIF(⑳商品別1食労務費!$C$5:$C$124,$S31,⑳商品別1食労務費!$F$5:$F$124)/$AA31,$AB31/$X31)) | AF31: =IF($T31="",0,IF($AA31>0,$AB31*SUMIF(⑳商品別1食労務費!$C$5:$C$124,$T31,⑳商品別1食労務費!$F$5:$F$124)/$AA31,$AB31/$X31)) | AG31: =IF($U31="",0,IF($AA31>0,$AB31*SUMIF(⑳商品別1食労務費!$C$5:$C$124,$U31,⑳商品別1食労務費!$F$5:$F$124)/$AA31,$AB31/$X31)) | AH31: =IF($V31="",0,IF($AA31>0,$AB31*SUMIF(⑳商品別1食労務費!$C$5:$C$124,$V31,⑳商品別1食労務費!$F$5:$F$124)/$AA31,$AB31/$X31)) | AI31: =IF($W31="",0,IF($AA31>0,$AB31*SUMIF(⑳商品別1食労務費!$C$5:$C$124,$W31,⑳商品別1食労務費!$F$5:$F$124)/$AA31,$AB31/$X31))
A32: 28 | B32: 釜製造 | C32: ホテルロール | D32: 0.19166667 | E32: 0.20555556 | F32: 5 | G32: 15 | H32: 1 | I32: 16 | K32: =IF(F32>0,I32/(F32/60),0) | L32: =IF(AND(ISNUMBER(F32),J32>0),J32/(F32/60),"") | M32: =IF(OR(ISNUMBER(SEARCH("サニテーション",C32)),ISNUMBER(SEARCH("客注",C32)),ISNUMBER(SEARCH("切り替え",C32)),ISNUMBER(SEARCH("切替",C32)),NOT(ISNUMBER(H32))),"",IF(ISNUMBER(G32),G32/60*H32*④前提設定!$B$4,IF(AND(G32="",ISNUMBER(F32)),F32/60*H32*④前提設定!$B$4,""))) | N32: =IF(I32>0,M32/I32,"") | O32: =IF(AND(J32>0,ISNUMBER(M32)),M32/J32,"") | R32: ふわもちホテルロール３個 | S32: ふわもちホテルロール８個入 | T32: ふわもちホテルロール１６個 | U32: Ｓふわもちホテルロール８個 | V32: Ｓふわもちホテルロール１６ | W32: ホテルロールＫＩＴ ４０個 | X32: =COUNTA(R32:W32) | Y32: =IF(AND($X32>0,ISNUMBER($M32)),$M32/$X32,"") | Z32: =IF($X32=0,"",IF(COUNTIF(⑳商品別1食労務費!$C$5:$C$124,$R32)+COUNTIF(⑳商品別1食労務費!$C$5:$C$124,$S32)+COUNTIF(⑳商品別1食労務費!$C$5:$C$124,$T32)+COUNTIF(⑳商品別1食労務費!$C$5:$C$124,$U32)+COUNTIF(⑳商品別1食労務費!$C$5:$C$124,$V32)+COUNTIF(⑳商品別1食労務費!$C$5:$C$124,$W32)=$X32,"OK","⑳に無い商品名")) | AA32: =SUMIF(⑳商品別1食労務費!$C$5:$C$124,$R32,⑳商品別1食労務費!$F$5:$F$124)+SUMIF(⑳商品別1食労務費!$C$5:$C$124,$S32,⑳商品別1食労務費!$F$5:$F$124)+SUMIF(⑳商品別1食労務費!$C$5:$C$124,$T32,⑳商品別1食労務費!$F$5:$F$124)+SUMIF(⑳商品別1食労務費!$C$5:$C$124,$U32,⑳商品別1食労務費!$F$5:$F$124)+SUMIF(⑳商品別1食労務費!$C$5:$C$124,$V32,⑳商品別1食労務費!$F$5:$F$124)+SUMIF(⑳商品別1食労務費!$C$5:$C$124,$W32,⑳商品別1食労務費!$F$5:$F$124) | AB32: =IF(ISNUMBER($M32),$M32,0) | AD32: =IF($R32="",0,IF($AA32>0,$AB32*SUMIF(⑳商品別1食労務費!$C$5:$C$124,$R32,⑳商品別1食労務費!$F$5:$F$124)/$AA32,$AB32/$X32)) | AE32: =IF($S32="",0,IF($AA32>0,$AB32*SUMIF(⑳商品別1食労務費!$C$5:$C$124,$S32,⑳商品別1食労務費!$F$5:$F$124)/$AA32,$AB32/$X32)) | AF32: =IF($T32="",0,IF($AA32>0,$AB32*SUMIF(⑳商品別1食労務費!$C$5:$C$124,$T32,⑳商品別1食労務費!$F$5:$F$124)/$AA32,$AB32/$X32)) | AG32: =IF($U32="",0,IF($AA32>0,$AB32*SUMIF(⑳商品別1食労務費!$C$5:$C$124,$U32,⑳商品別1食労務費!$F$5:$F$124)/$AA32,$AB32/$X32)) | AH32: =IF($V32="",0,IF($AA32>0,$AB32*SUMIF(⑳商品別1食労務費!$C$5:$C$124,$V32,⑳商品別1食労務費!$F$5:$F$124)/$AA32,$AB32/$X32)) | AI32: =IF($W32="",0,IF($AA32>0,$AB32*SUMIF(⑳商品別1食労務費!$C$5:$C$124,$W32,⑳商品別1食労務費!$F$5:$F$124)/$AA32,$AB32/$X32))
A33: 29 | B33: 釜製造 | C33: ホテルロール | D33: 0.20555556 | E33: 0.21944444 | F33: 5 | G33: 15 | H33: 1 | I33: 16 | K33: =IF(F33>0,I33/(F33/60),0) | L33: =IF(AND(ISNUMBER(F33),J33>0),J33/(F33/60),"") | M33: =IF(OR(ISNUMBER(SEARCH("サニテーション",C33)),ISNUMBER(SEARCH("客注",C33)),ISNUMBER(SEARCH("切り替え",C33)),ISNUMBER(SEARCH("切替",C33)),NOT(ISNUMBER(H33))),"",IF(ISNUMBER(G33),G33/60*H33*④前提設定!$B$4,IF(AND(G33="",ISNUMBER(F33)),F33/60*H33*④前提設定!$B$4,""))) | N33: =IF(I33>0,M33/I33,"") | O33: =IF(AND(J33>0,ISNUMBER(M33)),M33/J33,"") | R33: ふわもちホテルロール３個 | S33: ふわもちホテルロール８個入 | T33: ふわもちホテルロール１６個 | U33: Ｓふわもちホテルロール８個 | V33: Ｓふわもちホテルロール１６ | W33: ホテルロールＫＩＴ ４０個 | X33: =COUNTA(R33:W33) | Y33: =IF(AND($X33>0,ISNUMBER($M33)),$M33/$X33,"") | Z33: =IF($X33=0,"",IF(COUNTIF(⑳商品別1食労務費!$C$5:$C$124,$R33)+COUNTIF(⑳商品別1食労務費!$C$5:$C$124,$S33)+COUNTIF(⑳商品別1食労務費!$C$5:$C$124,$T33)+COUNTIF(⑳商品別1食労務費!$C$5:$C$124,$U33)+COUNTIF(⑳商品別1食労務費!$C$5:$C$124,$V33)+COUNTIF(⑳商品別1食労務費!$C$5:$C$124,$W33)=$X33,"OK","⑳に無い商品名")) | AA33: =SUMIF(⑳商品別1食労務費!$C$5:$C$124,$R33,⑳商品別1食労務費!$F$5:$F$124)+SUMIF(⑳商品別1食労務費!$C$5:$C$124,$S33,⑳商品別1食労務費!$F$5:$F$124)+SUMIF(⑳商品別1食労務費!$C$5:$C$124,$T33,⑳商品別1食労務費!$F$5:$F$124)+SUMIF(⑳商品別1食労務費!$C$5:$C$124,$U33,⑳商品別1食労務費!$F$5:$F$124)+SUMIF(⑳商品別1食労務費!$C$5:$C$124,$V33,⑳商品別1食労務費!$F$5:$F$124)+SUMIF(⑳商品別1食労務費!$C$5:$C$124,$W33,⑳商品別1食労務費!$F$5:$F$124) | AB33: =IF(ISNUMBER($M33),$M33,0) | AD33: =IF($R33="",0,IF($AA33>0,$AB33*SUMIF(⑳商品別1食労務費!$C$5:$C$124,$R33,⑳商品別1食労務費!$F$5:$F$124)/$AA33,$AB33/$X33)) | AE33: =IF($S33="",0,IF($AA33>0,$AB33*SUMIF(⑳商品別1食労務費!$C$5:$C$124,$S33,⑳商品別1食労務費!$F$5:$F$124)/$AA33,$AB33/$X33)) | AF33: =IF($T33="",0,IF($AA33>0,$AB33*SUMIF(⑳商品別1食労務費!$C$5:$C$124,$T33,⑳商品別1食労務費!$F$5:$F$124)/$AA33,$AB33/$X33)) | AG33: =IF($U33="",0,IF($AA33>0,$AB33*SUMIF(⑳商品別1食労務費!$C$5:$C$124,$U33,⑳商品別1食労務費!$F$5:$F$124)/$AA33,$AB33/$X33)) | AH33: =IF($V33="",0,IF($AA33>0,$AB33*SUMIF(⑳商品別1食労務費!$C$5:$C$124,$V33,⑳商品別1食労務費!$F$5:$F$124)/$AA33,$AB33/$X33)) | AI33: =IF($W33="",0,IF($AA33>0,$AB33*SUMIF(⑳商品別1食労務費!$C$5:$C$124,$W33,⑳商品別1食労務費!$F$5:$F$124)/$AA33,$AB33/$X33))
